Workbook

Sheet Diseño Curricular
A1: Curso | B1: 786 - Sistemas Organizacionales y Gerenciales 1 | F1: ⬅️ Seleccióna el curso.
A3: No. | B3: Competencia | C3: Unidad | D3: Tema | E3: Subtema | F3: Julio | G3: Semana
A4: 1 | B4: revisa la evolución de los sistemas de información en la empresa mediante el análisis de casos históricos y actuales con el fin de identificar tendencias y áreas de mejora | C4: 1 | D4: Evolución del sistema de información | E4: Definición de sistema de información | F4: Julio | G4: 1
A5: 2 | B5: revisa la evolución de los sistemas de información en la empresa mediante el análisis de casos históricos y actuales con el fin de identificar tendencias y áreas de mejora | C5: 1 | D5: Evolución del sistema de información | E5: Historia de los sistemas de información | F5: Julio | G5: 1
A6: 3 | B6: revisa la evolución de los sistemas de información en la empresa mediante el análisis de casos históricos y actuales con el fin de identificar tendencias y áreas de mejora | C6: 1 | D6: Evolución del sistema de información | E6: Tipos de sistemas de información | F6: Julio | G6: 1
A7: 4 | B7: revisa la evolución de los sistemas de información en la empresa mediante el análisis de casos históricos y actuales con el fin de identificar tendencias y áreas de mejora | C7: 1 | D7: Evolución del sistema de información | E7: Importancia en la empresa | F7: Julio | G7: 1
A8: 5 | B8: revisa la evolución de los sistemas de información en la empresa mediante el análisis de casos históricos y actuales con el fin de identificar tendencias y áreas de mejora | C8: 1 | D8: Evolución del sistema de información | E8: Desafíos actuales | F8: Julio | G8: 1
A9: 6 | B9: revisa la evolución de los sistemas de información en la empresa mediante el análisis de casos históricos y actuales con el fin de identificar tendencias y áreas de mejora | C9: 1 | D9: Evolución del sistema de información | E9: Ejemplos de sistemas en empresas | F9: Julio | G9: 1
A10: 7 | B10: revisa la evolución de los sistemas de información en la empresa mediante el análisis de casos históricos y actuales con el fin de identificar tendencias y áreas de mejora | C10: 1 | D10: Evolución del sistema de información | E10: Futuro de los sistemas de información | F10: Julio | G10: 1
A11: 8 | B11: moviliza habilidades de pensamiento crítico y resolución de problemas utilizando estudios de caso empresariales con el fin de fortalecer la toma de decisiones en entornos organizacionales | C11: 1 | D11: Gestión de recursos de información | E11: Fuentes de información | F11: Julio | G11: 1
A12: 9 | B12: moviliza habilidades de pensamiento crítico y resolución de problemas utilizando estudios de caso empresariales con el fin de fortalecer la toma de decisiones en entornos organizacionales | C12: 1 | D12: Gestión de recursos de información | E12: Clasificación de la información | F12: Julio | G12: 1
A13: 10 | B13: moviliza habilidades de pensamiento crítico y resolución de problemas utilizando estudios de caso empresariales con el fin de fortalecer la toma de decisiones en entornos organizacionales | C13: 1 | D13: Gestión de recursos de información | E13: Herramientas de gestión | F13: Julio | G13: 2
A14: 11 | B14: moviliza habilidades de pensamiento crítico y resolución de problemas utilizando estudios de caso empresariales con el fin de fortalecer la toma de decisiones en entornos organizacionales | C14: 1 | D14: Gestión de recursos de información | E14: Procesos de toma de decisiones | F14: Julio | G14: 2
A15: 12 | B15: moviliza habilidades de pensamiento crítico y resolución de problemas utilizando estudios de caso empresariales con el fin de fortalecer la toma de decisiones en entornos organizacionales | C15: 1 | D15: Gestión de recursos de información | E15: Ejemplos de gestión efectiva | F15: Julio | G15: 2
... A101: 98 | B101: combina técnicas de trabajo en equipo y colaboración interdisciplinaria empleando metodologías ágiles de gestión de proyectos con el fin de fomentar la innovación y eficiencia organizacional | C101: 5 | D101: Gamificación en educación | E101: Conclusiones sobre plataformas | F101: Octubre | G101: 11

Sheet S.Diagnostico
A1: Curso | B1: ='Diseño Curricular'!B1 -> 786 - Sistemas Organizacionales y Gerenciales 1
A3: Semana | B3: 0
A5: Valores
A6: * Recuerda que las competencias tambien forman valores identifica el valor o valores que transmitiras esa semana
A8: Nota | B8: En reunion del dia sabado 5 de abril de 2024 se tomo la decision por medio de un consenso entre los tutores que la primera semana se realizara el diagnistico del estudiente para ver los conocimientos con que cuenta
A10: No. | B10: Actividad | C10: Recurso Empleado | D10: Tiempo aproximado
A11: 1 | B11: Presentación Quien soy | C11: Presentacion
A12: 2 | B12: Conozco a los estudiantes | C12: Ruleta/ otros para escoger a 5 estudiantes para que se presenten
A13: 3 | B13: Diagnostico de conocimientos del curso anterior | C13: Cuestionario / Actividad
A14: 4 | B14: Exploramos el programa | C14: Lectura Explicativa
A15: 5 | B15: Diagnostico del nuevo contenido | C15: Cuestionario / Actividad

Sheet S.1
A1: Curso | B1: ='Diseño Curricular'!B1 -> 786 - Sistemas Organizacionales y Gerenciales 1
A3: Semana | B3: 1
A5: Valores | B5: Responsabilidad Valor: Cumplir con deberes y compromisos.
A6: * Recuerda que las competencias tambien forman valores identifica el valor o valores que transmitiras esa semana
A8: Cronograma | B8: Para mantener la atención, es recomendable variar la dinámica de la clase cada cierto tiempo, integrando actividades como preguntas, ejercicios prácticos o discusiones en grupo. Esto es clave para la educación por competencias, ya que el aprendizaje debe ser activo y aplicado.
A11: Ponderacion | B11: =SUM(C36:G36) -> 0 | F11: Total de tiempo | H11: =H25+H45+H53 -> 100
A13: Area de conocimiento
C14: Tipo de Recurso | D14: Presentacion | E14: Video | F14: Lectura Explicativa | G14: Otros
C15: Tiempo Max | D15: 25 | E15: 10 | F15: 25 | G15: 25
C16: Tiempo Planificado | D16: 25 | E16: 10 | F16: 25 | G16: 20
A17: No. | B17: Tema | C17: Subtema
A18: 1 | B18: =IFERROR(__xludf.DUMMYFUNCTION("FILTER('Diseño Curricular'!D:D,'Diseño Curricular'!G:G=$B$3)"),"Evolución del sistema de información") -> Evolución del sistema de información | C18: =IFERROR(__xludf.DUMMYFUNCTION("FILTER('Diseño Curricular'!E:E,'Diseño Curricular'!G:G=$B$3)"),"Definición de sistema de información") -> Definición de sistema de información | D18: X
A19: 2 | B19: =IFERROR(__xludf.DUMMYFUNCTION("""COMPUTED_VALUE"""),"Evolución del sistema de información") -> Evolución del sistema de información | C19: =IFERROR(__xludf.DUMMYFUNCTION("""COMPUTED_VALUE"""),"Historia de los sistemas de información") -> Historia de los sistemas de información | D19: X
A20: 3 | B20: =IFERROR(__xludf.DUMMYFUNCTION("""COMPUTED_VALUE"""),"Evolución del sistema de información") -> Evolución del sistema de información | C20: =IFERROR(__xludf.DUMMYFUNCTION("""COMPUTED_VALUE"""),"Tipos de sistemas de información") -> Tipos de sistemas de información | D20: X | E20: X | G20: X
A21: 4 | B21: =IFERROR(__xludf.DUMMYFUNCTION("""COMPUTED_VALUE"""),"Evolución del sistema de información") -> Evolución del sistema de información | C21: =IFERROR(__xludf.DUMMYFUNCTION("""COMPUTED_VALUE"""),"Importancia en la empresa") -> Importancia en la empresa | D21: X
A22: 5 | B22: =IFERROR(__xludf.DUMMYFUNCTION("""COMPUTED_VALUE"""),"Evolución del sistema de información") -> Evolución del sistema de información | C22: =IFERROR(__xludf.DUMMYFUNCTION("""COMPUTED_VALUE"""),"Desafíos actuales") -> Desafíos actuales | D22: X
A23: 6 | B23: =IFERROR(__xludf.DUMMYFUNCTION("""COMPUTED_VALUE"""),"Evolución del sistema de información") -> Evolución del sistema de información | C23: =IFERROR(__xludf.DUMMYFUNCTION("""COMPUTED_VALUE"""),"Ejemplos de sistemas en empresas") -> Ejemplos de sistemas en empresas | D23: X
A24: 7 | B24: =IFERROR(__xludf.DUMMYFUNCTION("""COMPUTED_VALUE"""),"Evolución del sistema de información") -> Evolución del sistema de información | C24: =IFERROR(__xludf.DUMMYFUNCTION("""COMPUTED_VALUE"""),"Futuro de los sistemas de información") -> Futuro de los sistemas de información | D24: X | E24: X
B25: =IFERROR(__xludf.DUMMYFUNCTION("""COMPUTED_VALUE"""),"Gestión de recursos de información") -> Gestión de recursos de información | C25: =IFERROR(__xludf.DUMMYFUNCTION("""COMPUTED_VALUE"""),"Fuentes de información") -> Fuentes de información | G25: Sub total de tiempo | H25: =SUM(D16:G16) -> 80
A26: Marca con una x en recurso que planificas usar para impartir el conocimiento | B26: =IFERROR(__xludf.DUMMYFUNCTION("""COMPUTED_VALUE"""),"Gestión de recursos de información") -> Gestión de recursos de información | C26: =IFERROR(__xludf.DUMMYFUNCTION("""COMPUTED_VALUE"""),"Clasificación de la información") -> Clasificación de la información
A27: Otros : puedes modificarlo e indicar que recurso usarias por ejemplo simuladores
A29: Area de Habilidades
A30: Recordatorio
A31: Dentro de los 100 minutos de clase toma en cuenta incluir un tiempo para formar la habilidad del estudiante. Aprender haciendo.
A33: No. | B33: Tipo | C33: Ejercicio | D33: Practica | E33: Actividad | F33: Otros | G33: Cuestionario / Corto
B34: Tiempo Maximo | C34: 25 | D34: 25 | E34: 25 | F34: 25 | G34: 15
B35: Tiempo Planificado | C35: 10
B36: Ponderacion
B37: Competencia
A38: 1 | B38: valida metodologías de gestión del cambio y rediseño de procesos organizativos utilizando modelos de cambio organizativo y técnicas de reingeniería con el fin de garantizar la incorporación efectiva de las TIC | C38: X
A39: 2 | B39: contrasta ideas, soluciones y propuestas relacionadas con sistemas de información utilizando herramientas de comunicación efectiva con el fin de facilitar la colaboración y comprensión en la organización | C39: X
A40: 3
A41: 4
A42: 5
A43: 6
A44: 7
G45: Sub total de tiempo | H45: =SUM(C35:G35) -> 10
A46: Marca con una x en recurso que planificas usar para impartir el conocimiento
A47: Otros : puedes modificarlo e indicar que recurso usarias por ejemplo exposiciones
A48: Cierre
...

Sheet S.2
A1: Curso | B1: ='Diseño Curricular'!B1 -> 786 - Sistemas Organizacionales y Gerenciales 1
A3: Semana | B3: 2
A5: Valores | B5: Respeto Valor: Tratar a los demás con dignidad y cortesía.
A6: * Recuerda que las competencias tambien forman valores identifica el valor o valores que transmitiras esa semana
A8: Cronograma | B8: Para mantener la atención, es recomendable variar la dinámica de la clase cada cierto tiempo, integrando actividades como preguntas, ejercicios prácticos o discusiones en grupo. Esto es clave para la educación por competencias, ya que el aprendizaje debe ser activo y aplicado.
A11: Ponderacion | B11: =SUM(C36:G36) -> 0 | F11: Total de tiempo | H11: =H25+H45+H53 -> 100
A13: Area de conocimiento
C14: Tipo de Recurso | D14: Presentacion | E14: Video | F14: Lectura Explicativa | G14: Otros
C15: Tiempo Max | D15: 25 | E15: 10 | F15: 25 | G15: 25
C16: Tiempo Planificado | D16: 25 | E16: 10 | F16: 25 | G16: 20
A17: No. | B17: Tema | C17: Subtema
A18: 1 | B18: =IFERROR(__xludf.DUMMYFUNCTION("FILTER('Diseño Curricular'!D:D,'Diseño Curricular'!G:G=$B$3)"),"Gestión de recursos de información") -> Gestión de recursos de información | C18: =IFERROR(__xludf.DUMMYFUNCTION("FILTER('Diseño Curricular'!E:E,'Diseño Curricular'!G:G=$B$3)"),"Herramientas de gestión") -> Herramientas de gestión | D18: X | F18: X
A19: 2 | B19: =IFERROR(__xludf.DUMMYFUNCTION("""COMPUTED_VALUE"""),"Gestión de recursos de información") -> Gestión de recursos de información | C19: =IFERROR(__xludf.DUMMYFUNCTION("""COMPUTED_VALUE"""),"Procesos de toma de decisiones") -> Procesos de toma de decisiones | D19: X
A20: 3 | B20: =IFERROR(__xludf.DUMMYFUNCTION("""COMPUTED_VALUE"""),"Gestión de recursos de información") -> Gestión de recursos de información | C20: =IFERROR(__xludf.DUMMYFUNCTION("""COMPUTED_VALUE"""),"Ejemplos de gestión efectiva") -> Ejemplos de gestión efectiva | D20: X
A21: 4 | B21: =IFERROR(__xludf.DUMMYFUNCTION("""COMPUTED_VALUE"""),"Gestión de recursos de información") -> Gestión de recursos de información | C21: =IFERROR(__xludf.DUMMYFUNCTION("""COMPUTED_VALUE"""),"Impacto en la organización") -> Impacto en la organización | D21: X | G21: X
A22: 5 | B22: =IFERROR(__xludf.DUMMYFUNCTION("""COMPUTED_VALUE"""),"Gestión de recursos de información") -> Gestión de recursos de información | C22: =IFERROR(__xludf.DUMMYFUNCTION("""COMPUTED_VALUE"""),"Estudio de caso") -> Estudio de caso | D22: X | E22: X
A23: 6 | B23: =IFERROR(__xludf.DUMMYFUNCTION("""COMPUTED_VALUE"""),"Business Analytics") -> Business Analytics | C23: =IFERROR(__xludf.DUMMYFUNCTION("""COMPUTED_VALUE"""),"Definición de Business Analytics") -> Definición de Business Analytics | D23: X
A24: 7 | B24: =IFERROR(__xludf.DUMMYFUNCTION("""COMPUTED_VALUE"""),"Business Analytics") -> Business Analytics | C24: =IFERROR(__xludf.DUMMYFUNCTION("""COMPUTED_VALUE"""),"Herramientas de análisis") -> Herramientas de análisis | D24: X
G25: Sub total de tiempo | H25: =SUM(D16:G16) -> 80
A26: Marca con una x en recurso que planificas usar para impartir el conocimiento
A27: Otros : puedes modificarlo e indicar que recurso usarias por ejemplo simuladores
A29: Area de Habilidades
A30: Recordatorio
A31: Dentro de los 100 minutos de clase toma en cuenta incluir un tiempo para formar la habilidad del estudiante. Aprender haciendo.
A33: No. | B33: Tipo | C33: Ejercicio | D33: Practica | E33: Actividad | F33: Otros | G33: Cuestionario / Corto
B34: Tiempo Maximo | C34: 25 | D34: 25 | E34: 25 | F34: 25 | G34: 15
B35: Tiempo Planificado | C35: 10
B36: Ponderacion
B37: Competencia
A38: 1 | B38: valida metodologías de gestión del cambio y rediseño de procesos organizativos utilizando modelos de cambio organizativo y técnicas de reingeniería con el fin de garantizar la incorporación efectiva de las TIC
A39: 2 | B39: contrasta ideas, soluciones y propuestas relacionadas con sistemas de información utilizando herramientas de comunicación efectiva con el fin de facilitar la colaboración y comprensión en la organización
A40: 3
A41: 4
A42: 5
A43: 6
A44: 7
G45: Sub total de tiempo | H45: =SUM(C35:G35) -> 10
A46: Marca con una x en recurso que planificas usar para impartir el conocimiento
A47: Otros : puedes modificarlo e indicar que recurso usarias por ejemplo exposiciones
A48: Cierre
...

Sheet S.3
A1: Curso | B1: ='Diseño Curricular'!B1 -> 786 - Sistemas Organizacionales y Gerenciales 1
A3: Semana | B3: 3
A5: Valores | B5: Perseverancia Valor: Mantenerse constante ante los retos.
A6: * Recuerda que las competencias tambien forman valores identifica el valor o valores que transmitiras esa semana
A8: Cronograma | B8: Para mantener la atención, es recomendable variar la dinámica de la clase cada cierto tiempo, integrando actividades como preguntas, ejercicios prácticos o discusiones en grupo. Esto es clave para la educación por competencias, ya que el aprendizaje debe ser activo y aplicado.
A11: Ponderacion | B11: =SUM(C36:G36) -> 0 | F11: Total de tiempo | H11: =H25+H45+H53 -> 100
A13: Area de conocimiento
C14: Tipo de Recurso | D14: Presentacion | E14: Video | F14: Lectura Explicativa | G14: Cuestionario / Corto
C15: Tiempo Max | D15: 25 | E15: 10 | F15: 25 | G15: 25
C16: Tiempo Planificado | D16: 20 | E16: 10 | F16: 25 | G16: 25
A17: No. | B17: Tema | C17: Subtema
A18: 1 | B18: =IFERROR(__xludf.DUMMYFUNCTION("FILTER('Diseño Curricular'!D:D,'Diseño Curricular'!G:G=$B$3)"),"Business Analytics") -> Business Analytics | C18: =IFERROR(__xludf.DUMMYFUNCTION("FILTER('Diseño Curricular'!E:E,'Diseño Curricular'!G:G=$B$3)"),"Importancia en la toma de decisiones") -> Importancia en la toma de decisiones | D18: X
A19: 2 | B19: =IFERROR(__xludf.DUMMYFUNCTION("""COMPUTED_VALUE"""),"Business Analytics") -> Business Analytics | C19: =IFERROR(__xludf.DUMMYFUNCTION("""COMPUTED_VALUE"""),"Ejemplos de Business Analytics") -> Ejemplos de Business Analytics | D19: X
A20: 3 | B20: =IFERROR(__xludf.DUMMYFUNCTION("""COMPUTED_VALUE"""),"Business Analytics") -> Business Analytics | C20: =IFERROR(__xludf.DUMMYFUNCTION("""COMPUTED_VALUE"""),"Casos de éxito") -> Casos de éxito | D20: X | E20: X | F20: X
A21: 4 | B21: =IFERROR(__xludf.DUMMYFUNCTION("""COMPUTED_VALUE"""),"Business Analytics") -> Business Analytics | C21: =IFERROR(__xludf.DUMMYFUNCTION("""COMPUTED_VALUE"""),"Integración con sistemas de información") -> Integración con sistemas de información | D21: X
A22: 5 | B22: =IFERROR(__xludf.DUMMYFUNCTION("""COMPUTED_VALUE"""),"Business Analytics") -> Business Analytics | C22: =IFERROR(__xludf.DUMMYFUNCTION("""COMPUTED_VALUE"""),"Tendencias futuras") -> Tendencias futuras | D22: X | G22: X
A23: 6 | B23: =IFERROR(__xludf.DUMMYFUNCTION("""COMPUTED_VALUE"""),"La gestión del conocimiento") -> La gestión del conocimiento | C23: =IFERROR(__xludf.DUMMYFUNCTION("""COMPUTED_VALUE"""),"Concepto de gestión del conocimiento") -> Concepto de gestión del conocimiento | D23: X
A24: 7 | B24: =IFERROR(__xludf.DUMMYFUNCTION("""COMPUTED_VALUE"""),"La gestión del conocimiento") -> La gestión del conocimiento | C24: =IFERROR(__xludf.DUMMYFUNCTION("""COMPUTED_VALUE"""),"Estrategias de gestión") -> Estrategias de gestión | D24: X
G25: Sub total de tiempo | H25: =SUM(D16:G16) -> 80
A26: Marca con una x en recurso que planificas usar para impartir el conocimiento
A27: Otros : puedes modificarlo e indicar que recurso usarias por ejemplo simuladores
A29: Area de Habilidades
A30: Recordatorio
A31: Dentro de los 100 minutos de clase toma en cuenta incluir un tiempo para formar la habilidad del estudiante. Aprender haciendo.
A33: No. | B33: Tipo | C33: Ejercicio | D33: Practica | E33: Actividad | F33: Otros | G33: Cuestionario
B34: Tiempo Maximo | C34: 25 | D34: 25 | E34: 25 | F34: 25 | G34: 15
B35: Tiempo Planificado | C35: 10
B36: Ponderacion
B37: Competencia
A38: 1 | B38: combina técnicas de trabajo en equipo y colaboración interdisciplinaria empleando metodologías ágiles de gestión de proyectos con el fin de fomentar la innovación y eficiencia organizacional
A39: 2
A40: 3
A41: 4
A42: 5
A43: 6
A44: 7
G45: Sub total de tiempo | H45: =SUM(C35:G35) -> 10
A46: Marca con una x en recurso que planificas usar para impartir el conocimiento
A47: Otros : puedes modificarlo e indicar que recurso usarias por ejemplo exposiciones
A48: Cierre
...

Sheet S.4
A1: Curso | B1: ='Diseño Curricular'!B1 -> 786 - Sistemas Organizacionales y Gerenciales 1
A3: Semana | B3: 4
A5: Valores | B5: Honestidad Valor: Actuar con verdad y coherencia.
A6: * Recuerda que las competencias tambien forman valores identifica el valor o valores que transmitiras esa semana
A8: Cronograma | B8: Para mantener la atención, es recomendable variar la dinámica de la clase cada cierto tiempo, integrando actividades como preguntas, ejercicios prácticos o discusiones en grupo. Esto es clave para la educación por competencias, ya que el aprendizaje debe ser activo y aplicado.
A11: Ponderacion | B11: =SUM(C36:G36) -> 0 | F11: Total de tiempo | H11: =H25+H45+H53 -> 100
A13: Area de conocimiento
C14: Tipo de Recurso | D14: Presentacion | E14: Video | F14: Lectura Explicativa | G14: Otros
C15: Tiempo Max | D15: 25 | E15: 10 | F15: 25 | G15: 25
C16: Tiempo Planificado | D16: 25 | E16: 10 | F16: 25 | G16: 25
A17: No. | B17: Tema | C17: Subtema
A18: 1 | B18: =IFERROR(__xludf.DUMMYFUNCTION("FILTER('Diseño Curricular'!D:D,'Diseño Curricular'!G:G=$B$3)"),"La gestión del conocimiento") -> La gestión del conocimiento | C18: =IFERROR(__xludf.DUMMYFUNCTION("FILTER('Diseño Curricular'!E:E,'Diseño Curricular'!G:G=$B$3)"),"Herramientas tecnológicas") -> Herramientas tecnológicas | D18: X
A19: 2 | B19: =IFERROR(__xludf.DUMMYFUNCTION("""COMPUTED_VALUE"""),"La gestión del conocimiento") -> La gestión del conocimiento | C19: =IFERROR(__xludf.DUMMYFUNCTION("""COMPUTED_VALUE"""),"Impacto en la organización") -> Impacto en la organización | D19: X
A20: 3 | B20: =IFERROR(__xludf.DUMMYFUNCTION("""COMPUTED_VALUE"""),"La gestión del conocimiento") -> La gestión del conocimiento | C20: =IFERROR(__xludf.DUMMYFUNCTION("""COMPUTED_VALUE"""),"Ejemplos de gestión del conocimiento") -> Ejemplos de gestión del conocimiento | D20: X | E20: X
A21: 4 | B21: =IFERROR(__xludf.DUMMYFUNCTION("""COMPUTED_VALUE"""),"La gestión del conocimiento") -> La gestión del conocimiento | C21: =IFERROR(__xludf.DUMMYFUNCTION("""COMPUTED_VALUE"""),"Estudio de caso") -> Estudio de caso | D21: X
A22: 5 | B22: =IFERROR(__xludf.DUMMYFUNCTION("""COMPUTED_VALUE"""),"La gestión del conocimiento") -> La gestión del conocimiento | C22: =IFERROR(__xludf.DUMMYFUNCTION("""COMPUTED_VALUE"""),"Futuro de la gestión del conocimiento") -> Futuro de la gestión del conocimiento | D22: X | F22: X
A23: 6 | B23: =IFERROR(__xludf.DUMMYFUNCTION("""COMPUTED_VALUE"""),"Papel estratégico de las TIC") -> Papel estratégico de las TIC | C23: =IFERROR(__xludf.DUMMYFUNCTION("""COMPUTED_VALUE"""),"Definición de TIC") -> Definición de TIC | D23: X | G23: X
A24: 7
G25: Sub total de tiempo | H25: =SUM(D16:G16) -> 85
A26: Marca con una x en recurso que planificas usar para impartir el conocimiento
A27: Otros : puedes modificarlo e indicar que recurso usarias por ejemplo simuladores
A29: Area de Habilidades
A30: Recordatorio
A31: Dentro de los 100 minutos de clase toma en cuenta incluir un tiempo para formar la habilidad del estudiante. Aprender haciendo.
A33: No. | B33: Tipo | C33: Ejercicio | D33: Practica | E33: Actividad | F33: Otros | G33: Cuestionario / Corto
B34: Tiempo Maximo | C34: 25 | D34: 25 | E34: 25 | F34: 25 | G34: 15
B35: Tiempo Planificado | C35: 5
B36: Ponderacion
B37: Competencia
A38: 1 | B38: contrasta ideas, soluciones y propuestas relacionadas con sistemas de información utilizando herramientas de comunicación efectiva con el fin de facilitar la colaboración y comprensión en la organización
A39: 2
A40: 3
A41: 4
A42: 5
A43: 6
A44: 7
G45: Sub total de tiempo | H45: =SUM(C35:G35) -> 5
A46: Marca con una x en recurso que planificas usar para impartir el conocimiento
A47: Otros : puedes modificarlo e indicar que recurso usarias por ejemplo exposiciones
A48: Cierre
...

Sheet S.5
A1: Curso | B1: ='Diseño Curricular'!B1 -> 786 - Sistemas Organizacionales y Gerenciales 1
A3: Semana | B3: 5
A5: Valores | B5: Colaboración Valor: Trabajar juntos hacia un objetivo común.
A6: * Recuerda que las competencias tambien forman valores identifica el valor o valores que transmitiras esa semana
A8: Cronograma | B8: Para mantener la atención, es recomendable variar la dinámica de la clase cada cierto tiempo, integrando actividades como preguntas, ejercicios prácticos o discusiones en grupo. Esto es clave para la educación por competencias, ya que el aprendizaje debe ser activo y aplicado.
A11: Ponderacion | B11: =SUM(C36:G36) -> 0 | F11: Total de tiempo | H11: =H25+H45+H53 -> 100
A13: Area de conocimiento
C14: Tipo de Recurso | D14: Presentacion | E14: Video | F14: Lectura Explicativa | G14: Otros
C15: Tiempo Max | D15: 25 | E15: 10 | F15: 25 | G15: 25
C16: Tiempo Planificado | D16: 20 | E16: 5 | F16: 25 | G16: 25
A17: No. | B17: Tema | C17: Subtema
A18: 1 | B18: =IFERROR(__xludf.DUMMYFUNCTION("FILTER('Diseño Curricular'!D:D,'Diseño Curricular'!G:G=$B$3)"),"Papel estratégico de las TIC") -> Papel estratégico de las TIC | C18: =IFERROR(__xludf.DUMMYFUNCTION("FILTER('Diseño Curricular'!E:E,'Diseño Curricular'!G:G=$B$3)"),"Historia de las TIC") -> Historia de las TIC | D18: X | F18: X
A19: 2 | B19: =IFERROR(__xludf.DUMMYFUNCTION("""COMPUTED_VALUE"""),"Papel estratégico de las TIC") -> Papel estratégico de las TIC | C19: =IFERROR(__xludf.DUMMYFUNCTION("""COMPUTED_VALUE"""),"Tipos de TIC") -> Tipos de TIC | D19: X
A20: 3 | B20: =IFERROR(__xludf.DUMMYFUNCTION("""COMPUTED_VALUE"""),"Papel estratégico de las TIC") -> Papel estratégico de las TIC | C20: =IFERROR(__xludf.DUMMYFUNCTION("""COMPUTED_VALUE"""),"Importancia en la empresa") -> Importancia en la empresa | D20: X | E20: X
A21: 4 | B21: =IFERROR(__xludf.DUMMYFUNCTION("""COMPUTED_VALUE"""),"Papel estratégico de las TIC") -> Papel estratégico de las TIC | C21: =IFERROR(__xludf.DUMMYFUNCTION("""COMPUTED_VALUE"""),"Desafíos actuales") -> Desafíos actuales | D21: X
A22: 5 | B22: =IFERROR(__xludf.DUMMYFUNCTION("""COMPUTED_VALUE"""),"Papel estratégico de las TIC") -> Papel estratégico de las TIC | C22: =IFERROR(__xludf.DUMMYFUNCTION("""COMPUTED_VALUE"""),"Ejemplos de uso de TIC en empresas") -> Ejemplos de uso de TIC en empresas | D22: X
A23: 6 | B23: =IFERROR(__xludf.DUMMYFUNCTION("""COMPUTED_VALUE"""),"Papel estratégico de las TIC") -> Papel estratégico de las TIC | C23: =IFERROR(__xludf.DUMMYFUNCTION("""COMPUTED_VALUE"""),"Futuro de las TIC") -> Futuro de las TIC | D23: X | G23: X
A24: 7 | B24: =IFERROR(__xludf.DUMMYFUNCTION("""COMPUTED_VALUE"""),"Sistemas de información en negocios globales") -> Sistemas de información en negocios globales | C24: =IFERROR(__xludf.DUMMYFUNCTION("""COMPUTED_VALUE"""),"Definición de sistemas en negocios globales") -> Definición de sistemas en negocios globales | D24: X
G25: Sub total de tiempo | H25: =SUM(D16:G16) -> 75
A26: Marca con una x en recurso que planificas usar para impartir el conocimiento
A27: Otros : puedes modificarlo e indicar que recurso usarias por ejemplo simuladores
A29: Area de Habilidades
A30: Recordatorio
A31: Dentro de los 100 minutos de clase toma en cuenta incluir un tiempo para formar la habilidad del estudiante. Aprender haciendo.
A33: No. | B33: Tipo | C33: Ejercicio | D33: Practica | E33: Actividad | F33: Otros | G33: Cuestionario / Corto
B34: Tiempo Maximo | C34: 25 | D34: 25 | E34: 25 | F34: 25 | G34: 15
B35: Tiempo Planificado | C35: 15
B36: Ponderacion
B37: Competencia
A38: 1 | B38: contrasta ideas, soluciones y propuestas relacionadas con sistemas de información utilizando herramientas de comunicación efectiva con el fin de facilitar la colaboración y comprensión en la organización
A39: 2 | B39: valida metodologías de gestión del cambio y rediseño de procesos organizativos utilizando modelos de cambio organizativo y técnicas de reingeniería con el fin de garantizar la incorporación efectiva de las TIC
A40: 3
A41: 4
A42: 5
A43: 6
A44: 7
G45: Sub total de tiempo | H45: =SUM(C35:G35) -> 15
A46: Marca con una x en recurso que planificas usar para impartir el conocimiento
A47: Otros : puedes modificarlo e indicar que recurso usarias por ejemplo exposiciones
A48: Cierre
...

Sheet S.6
A1: 7 | B1: ='Diseño Curricular'!B1 -> 786 - Sistemas Organizacionales y Gerenciales 1
A3: Semana | B3: 6
A5: Valores | B5: Innovación: Fomentar la capacidad de adaptarse a los cambios tecnológicos y proponer soluciones creativas en un entorno empresarial global.
A6: * Recuerda que las competencias tambien forman valores identifica el valor o valores que transmitiras esa semana
A8: Cronograma | B8: Para mantener la atención, es recomendable variar la dinámica de la clase cada cierto tiempo, integrando actividades como preguntas, ejercicios prácticos o discusiones en grupo. Esto es clave para la educación por competencias, ya que el aprendizaje debe ser activo y aplicado.
A11: Ponderacion | B11: =SUM(C36:G36) -> 0 | F11: Total de tiempo | H11: =H25+H45+H53 -> 100
A13: Area de conocimiento
C14: Tipo de Recurso | D14: Presentacion | E14: Video | F14: Lectura Explicativa | G14: Otros
C15: Tiempo Max | D15: 25 | E15: 10 | F15: 25 | G15: 25
C16: Tiempo Planificado | D16: 25 | E16: 10 | F16: 25 | G16: 25
A17: No. | B17: Tema | C17: Subtema
A18: 1 | B18: =IFERROR(__xludf.DUMMYFUNCTION("FILTER('Diseño Curricular'!D:D,'Diseño Curricular'!G:G=$B$3)"),"Sistemas de información en negocios globales") -> Sistemas de información en negocios globales | C18: =IFERROR(__xludf.DUMMYFUNCTION("FILTER('Diseño Curricular'!E:E,'Diseño Curricular'!G:G=$B$3)"),"Impacto en la globalización") -> Impacto en la globalización | D18: X | E18: X
A19: 2 | B19: =IFERROR(__xludf.DUMMYFUNCTION("""COMPUTED_VALUE"""),"Sistemas de información en negocios globales") -> Sistemas de información en negocios globales | C19: =IFERROR(__xludf.DUMMYFUNCTION("""COMPUTED_VALUE"""),"Ejemplos de implementación") -> Ejemplos de implementación | D19: X | G19: X
A20: 3 | B20: =IFERROR(__xludf.DUMMYFUNCTION("""COMPUTED_VALUE"""),"Sistemas de información en negocios globales") -> Sistemas de información en negocios globales | C20: =IFERROR(__xludf.DUMMYFUNCTION("""COMPUTED_VALUE"""),"Desafíos en la integración") -> Desafíos en la integración | D20: X
A21: 4 | B21: =IFERROR(__xludf.DUMMYFUNCTION("""COMPUTED_VALUE"""),"Sistemas de información en negocios globales") -> Sistemas de información en negocios globales | C21: =IFERROR(__xludf.DUMMYFUNCTION("""COMPUTED_VALUE"""),"Herramientas tecnológicas") -> Herramientas tecnológicas | D21: X
A22: 5 | B22: =IFERROR(__xludf.DUMMYFUNCTION("""COMPUTED_VALUE"""),"Sistemas de información en negocios globales") -> Sistemas de información en negocios globales | C22: =IFERROR(__xludf.DUMMYFUNCTION("""COMPUTED_VALUE"""),"Impacto en la cultura empresarial") -> Impacto en la cultura empresarial | D22: X
A23: 6 | B23: =IFERROR(__xludf.DUMMYFUNCTION("""COMPUTED_VALUE"""),"Sistemas de información en negocios globales") -> Sistemas de información en negocios globales | C23: =IFERROR(__xludf.DUMMYFUNCTION("""COMPUTED_VALUE"""),"Futuro de los negocios globales") -> Futuro de los negocios globales | D23: X | F23: X
A24: 7 | B24: =IFERROR(__xludf.DUMMYFUNCTION("""COMPUTED_VALUE"""),"Global e-business y colaboración") -> Global e-business y colaboración | C24: =IFERROR(__xludf.DUMMYFUNCTION("""COMPUTED_VALUE"""),"Definición de e-business") -> Definición de e-business | D24: X | E24: X
G25: Sub total de tiempo | H25: =SUM(D16:G16) -> 85
A26: Marca con una x en recurso que planificas usar para impartir el conocimiento
A27: Otros : puedes modificarlo e indicar que recurso usarias por ejemplo simuladores
A29: Area de Habilidades
A30: Recordatorio
A31: Dentro de los 100 minutos de clase toma en cuenta incluir un tiempo para formar la habilidad del estudiante. Aprender haciendo.
A33: No. | B33: Tipo | C33: Ejercicio | D33: Practica | E33: Actividad | F33: Otros | G33: Cuestionario / Corto
B34: Tiempo Maximo | C34: 25 | D34: 25 | E34: 25 | F34: 25 | G34: 15
B35: Tiempo Planificado | C35: 5
B36: Ponderacion | C36: 0
B37: Competencia
A38: 1 | B38: integra sistemas de información organizacionales (ERP, SCM, CRM) utilizando tecnologías de información y comunicación con el fin de apoyar la transformación digital y mejorar la toma de decisiones estratégicas | C38: X
A39: 2 | B39: moviliza habilidades de pensamiento crítico y resolución de problemas utilizando estudios de caso empresariales con el fin de fortalecer la toma de decisiones en entornos organizacionales | C39: X
A40: 3
A41: 4
A42: 5
A43: 6
A44: 7
G45: Sub total de tiempo | H45: =SUM(C35:G35) -> 5
A46: Marca con una x en recurso que planificas usar para impartir el conocimiento
A47: Otros : puedes modificarlo e indicar que recurso usarias por ejemplo exposiciones
A48: Cierre
...

Sheet S.7
A1: Curso | B1: ='Diseño Curricular'!B1 -> 786 - Sistemas Organizacionales y Gerenciales 1
A3: Semana | B3: 7
A5: Valores | B5: Responsabilidad: Promover la responsabilidad como valor clave al participar en entornos digitales y colaborativos, asumiendo compromisos éticos, profesionales y sociales al implementar o usar tecnologías en los negocios.
A6: * Recuerda que las competencias tambien forman valores identifica el valor o valores que transmitiras esa semana
A8: Cronograma | B8: Para mantener la atención, es recomendable variar la dinámica de la clase cada cierto tiempo, integrando actividades como preguntas, ejercicios prácticos o discusiones en grupo. Esto es clave para la educación por competencias, ya que el aprendizaje debe ser activo y aplicado.
A11: Ponderacion | B11: =SUM(C36:G36) -> 0 | F11: Total de tiempo | H11: =H25+H45+H53 -> 100
A13: Area de conocimiento
C14: Tipo de Recurso | D14: Presentacion | E14: Video | F14: Lectura Explicativa | G14: Otros
C15: Tiempo Max | D15: 25 | E15: 10 | F15: 25 | G15: 25
C16: Tiempo Planificado | D16: 25 | E16: 10 | F16: 25 | G16: 25
A17: No. | B17: Tema | C17: Subtema
A18: 1 | B18: =IFERROR(__xludf.DUMMYFUNCTION("FILTER('Diseño Curricular'!D:D,'Diseño Curricular'!G:G=$B$3)"),"Global e-business y colaboración") -> Global e-business y colaboración | C18: =IFERROR(__xludf.DUMMYFUNCTION("FILTER('Diseño Curricular'!E:E,'Diseño Curricular'!G:G=$B$3)"),"Estrategias de colaboración") -> Estrategias de colaboración | D18: X | E18: X
A19: 2 | B19: =IFERROR(__xludf.DUMMYFUNCTION("""COMPUTED_VALUE"""),"Global e-business y colaboración") -> Global e-business y colaboración | C19: =IFERROR(__xludf.DUMMYFUNCTION("""COMPUTED_VALUE"""),"Ejemplos de e-business") -> Ejemplos de e-business | D19: X | F19: X
A20: 3 | B20: =IFERROR(__xludf.DUMMYFUNCTION("""COMPUTED_VALUE"""),"Global e-business y colaboración") -> Global e-business y colaboración | C20: =IFERROR(__xludf.DUMMYFUNCTION("""COMPUTED_VALUE"""),"Herramientas para e-business") -> Herramientas para e-business | D20: X | E20: X | G20: X
A21: 4 | B21: =IFERROR(__xludf.DUMMYFUNCTION("""COMPUTED_VALUE"""),"Global e-business y colaboración") -> Global e-business y colaboración | C21: =IFERROR(__xludf.DUMMYFUNCTION("""COMPUTED_VALUE"""),"Casos de éxito") -> Casos de éxito | D21: X | F21: X
A22: 5 | B22: =IFERROR(__xludf.DUMMYFUNCTION("""COMPUTED_VALUE"""),"Global e-business y colaboración") -> Global e-business y colaboración | C22: =IFERROR(__xludf.DUMMYFUNCTION("""COMPUTED_VALUE"""),"Desafíos en e-business") -> Desafíos en e-business | D22: X | F22: X
A23: 6 | B23: =IFERROR(__xludf.DUMMYFUNCTION("""COMPUTED_VALUE"""),"Global e-business y colaboración") -> Global e-business y colaboración | C23: =IFERROR(__xludf.DUMMYFUNCTION("""COMPUTED_VALUE"""),"Futuro del e-business") -> Futuro del e-business | D23: X | F23: X
A24: 7 | B24: =IFERROR(__xludf.DUMMYFUNCTION("""COMPUTED_VALUE"""),"Problemas éticos y sociales en sistemas") -> Problemas éticos y sociales en sistemas | C24: =IFERROR(__xludf.DUMMYFUNCTION("""COMPUTED_VALUE"""),"Definición de problemas éticos") -> Definición de problemas éticos | D24: X | G24: X
G25: Sub total de tiempo | H25: =SUM(D16:G16) -> 85
A26: Marca con una x en recurso que planificas usar para impartir el conocimiento
A27: Otros : puedes modificarlo e indicar que recurso usarias por ejemplo simuladores
A29: Area de Habilidades
A30: Recordatorio
A31: Dentro de los 100 minutos de clase toma en cuenta incluir un tiempo para formar la habilidad del estudiante. Aprender haciendo.
A33: No. | B33: Tipo | C33: Ejercicio | D33: Practica | E33: Actividad | F33: Otros | G33: Cuestionario / Corto
B34: Tiempo Maximo | C34: 25 | D34: 25 | E34: 25 | F34: 25 | G34: 15
B35: Tiempo Planificado | C35: 5
B36: Ponderacion | C36: 0
B37: Competencia
A38: 1 | B38: diseña soluciones de sistemas de información geográfica (GIS) y de inteligencia de negocios (BI) utilizando software especializado con el fin de optimizar la visualización y análisis de datos estratégicos | C38: x
A39: 2 | B39: combina técnicas de trabajo en equipo y colaboración interdisciplinaria empleando metodologías ágiles de gestión de proyectos con el fin de fomentar la innovación y eficiencia organizacional | C39: x
A40: 3
A41: 4
A42: 5
A43: 6
A44: 7
G45: Sub total de tiempo | H45: =SUM(C35:G35) -> 5
A46: Marca con una x en recurso que planificas usar para impartir el conocimiento
A47: Otros : puedes modificarlo e indicar que recurso usarias por ejemplo exposiciones
A48: Cierre
...

Sheet S.8
A1: Curso | B1: ='Diseño Curricular'!B1 -> 786 - Sistemas Organizacionales y Gerenciales 1
A3: Semana | B3: 8
A5: Valores | B5: Integriadad: Fomentar la integridad como principio clave en el uso, diseño e implementación de tecnologías, promoviendo la honestidad, la ética profesional y la coherencia entre valores y acciones en el ámbito digital.
A6: * Recuerda que las competencias tambien forman valores identifica el valor o valores que transmitiras esa semana
A8: Cronograma | B8: Para mantener la atención, es recomendable variar la dinámica de la clase cada cierto tiempo, integrando actividades como preguntas, ejercicios prácticos o discusiones en grupo. Esto es clave para la educación por competencias, ya que el aprendizaje debe ser activo y aplicado.
A11: Ponderacion | B11: =SUM(C36:G36) -> 0 | F11: Total de tiempo | H11: =H25+H45+H53 -> 100
A13: Area de conocimiento
C14: Tipo de Recurso | D14: Presentacion | E14: Video | F14: Lectura Explicativa | G14: Otros
C15: Tiempo Max | D15: 25 | E15: 10 | F15: 25 | G15: 25
C16: Tiempo Planificado | D16: 25 | E16: 10 | F16: 25 | G16: 25
A17: No. | B17: Tema | C17: Subtema
A18: 1 | B18: =IFERROR(__xludf.DUMMYFUNCTION("FILTER('Diseño Curricular'!D:D,'Diseño Curricular'!G:G=$B$3)"),"Problemas éticos y sociales en sistemas") -> Problemas éticos y sociales en sistemas | C18: =IFERROR(__xludf.DUMMYFUNCTION("FILTER('Diseño Curricular'!E:E,'Diseño Curricular'!G:G=$B$3)"),"Ejemplos de problemas éticos") -> Ejemplos de problemas éticos | D18: X | G18: X
A19: 2 | B19: =IFERROR(__xludf.DUMMYFUNCTION("""COMPUTED_VALUE"""),"Problemas éticos y sociales en sistemas") -> Problemas éticos y sociales en sistemas | C19: =IFERROR(__xludf.DUMMYFUNCTION("""COMPUTED_VALUE"""),"Impacto social de las TIC") -> Impacto social de las TIC | D19: X | E19: X | F19: X
A20: 3 | B20: =IFERROR(__xludf.DUMMYFUNCTION("""COMPUTED_VALUE"""),"Problemas éticos y sociales en sistemas") -> Problemas éticos y sociales en sistemas | C20: =IFERROR(__xludf.DUMMYFUNCTION("""COMPUTED_VALUE"""),"Casos de estudio") -> Casos de estudio | D20: X | G20: X
A21: 4 | B21: =IFERROR(__xludf.DUMMYFUNCTION("""COMPUTED_VALUE"""),"Problemas éticos y sociales en sistemas") -> Problemas éticos y sociales en sistemas | C21: =IFERROR(__xludf.DUMMYFUNCTION("""COMPUTED_VALUE"""),"Desafíos éticos en la implementación") -> Desafíos éticos en la implementación | D21: X
A22: 5 | B22: =IFERROR(__xludf.DUMMYFUNCTION("""COMPUTED_VALUE"""),"Problemas éticos y sociales en sistemas") -> Problemas éticos y sociales en sistemas | C22: =IFERROR(__xludf.DUMMYFUNCTION("""COMPUTED_VALUE"""),"Futuro de la ética en TIC") -> Futuro de la ética en TIC | D22: X | F22: X
A23: 6 | B23: =IFERROR(__xludf.DUMMYFUNCTION("""COMPUTED_VALUE"""),"Problemas éticos y sociales en sistemas") -> Problemas éticos y sociales en sistemas | C23: =IFERROR(__xludf.DUMMYFUNCTION("""COMPUTED_VALUE"""),"Conclusiones sobre problemas éticos") -> Conclusiones sobre problemas éticos | D23: X
A24: 7 | B24: =IFERROR(__xludf.DUMMYFUNCTION("""COMPUTED_VALUE"""),"Clases de sistemas de información") -> Clases de sistemas de información | C24: =IFERROR(__xludf.DUMMYFUNCTION("""COMPUTED_VALUE"""),"Sistemas funcionales") -> Sistemas funcionales | D24: X | E24: X
B25: =IFERROR(__xludf.DUMMYFUNCTION("""COMPUTED_VALUE"""),"Clases de sistemas de información") -> Clases de sistemas de información | C25: =IFERROR(__xludf.DUMMYFUNCTION("""COMPUTED_VALUE"""),"ERP") -> ERP | G25: Sub total de tiempo | H25: =SUM(D16:G16) -> 85
A26: Marca con una x en recurso que planificas usar para impartir el conocimiento
A27: Otros : puedes modificarlo e indicar que recurso usarias por ejemplo simuladores
A29: Area de Habilidades
A30: Recordatorio
A31: Dentro de los 100 minutos de clase toma en cuenta incluir un tiempo para formar la habilidad del estudiante. Aprender haciendo.
A33: No. | B33: Tipo | C33: Ejercicio | D33: Practica | E33: Actividad | F33: Otros | G33: Cuestionario / Corto
B34: Tiempo Maximo | C34: 25 | D34: 25 | E34: 25 | F34: 25 | G34: 15
B35: Tiempo Planificado | C35: 5
B36: Ponderacion | C36: 0
B37: Competencia
A38: 1 | B38: combina técnicas de trabajo en equipo y colaboración interdisciplinaria empleando metodologías ágiles de gestión de proyectos con el fin de fomentar la innovación y eficiencia organizacional | C38: X
A39: 2 | B39: moviliza habilidades de pensamiento crítico y resolución de problemas utilizando estudios de caso empresariales con el fin de fortalecer la toma de decisiones en entornos organizacionales | C39: X
A40: 3
A41: 4
A42: 5
A43: 6
A44: 7
G45: Sub total de tiempo | H45: =SUM(C35:G35) -> 5
A46: Marca con una x en recurso que planificas usar para impartir el conocimiento
A47: Otros : puedes modificarlo e indicar que recurso usarias por ejemplo exposiciones
A48: Cierre
...

Sheet S.9
A1: Curso | B1: ='Diseño Curricular'!B1 -> 786 - Sistemas Organizacionales y Gerenciales 1
A3: Semana | B3: 9
A5: Valores | B5: Eficiencia: Promover la eficiencia como valor esencial al diseñar, integrar y utilizar sistemas de información, buscando siempre optimizar recursos, procesos y resultados dentro de una organización.
A6: * Recuerda que las competencias tambien forman valores identifica el valor o valores que transmitiras esa semana
A8: Cronograma | B8: Para mantener la atención, es recomendable variar la dinámica de la clase cada cierto tiempo, integrando actividades como preguntas, ejercicios prácticos o discusiones en grupo. Esto es clave para la educación por competencias, ya que el aprendizaje debe ser activo y aplicado.
A11: Ponderacion | B11: =SUM(C41:G41) -> 0 | F11: Total de tiempo | H11: =H30+H50+H58 -> 100
A13: Area de conocimiento
C14: Tipo de Recurso | D14: Presentacion | E14: Video | F14: Lectura Explicativa | G14: Otros
C15: Tiempo Max | D15: 25 | E15: 10 | F15: 25 | G15: 25
C16: Tiempo Planificado | D16: 25 | E16: 10 | F16: 25 | G16: 25
A17: No. | B17: Tema | C17: Subtema
A18: 1 | B18: =IFERROR(__xludf.DUMMYFUNCTION("FILTER('Diseño Curricular'!D:D,'Diseño Curricular'!G:G=$B$3)"),"Clases de sistemas de información") -> Clases de sistemas de información | C18: =IFERROR(__xludf.DUMMYFUNCTION("FILTER('Diseño Curricular'!E:E,'Diseño Curricular'!G:G=$B$3)"),"SCM") -> SCM | D18: x | E18: x | G18: x
A19: 2 | B19: =IFERROR(__xludf.DUMMYFUNCTION("""COMPUTED_VALUE"""),"Clases de sistemas de información") -> Clases de sistemas de información | C19: =IFERROR(__xludf.DUMMYFUNCTION("""COMPUTED_VALUE"""),"CRM") -> CRM | D19: x | E19: x | G19: x
A20: 3 | B20: =IFERROR(__xludf.DUMMYFUNCTION("""COMPUTED_VALUE"""),"Clases de sistemas de información") -> Clases de sistemas de información | C20: =IFERROR(__xludf.DUMMYFUNCTION("""COMPUTED_VALUE"""),"Sistemas distribuidos") -> Sistemas distribuidos | D20: x
A21: 4 | B21: =IFERROR(__xludf.DUMMYFUNCTION("""COMPUTED_VALUE"""),"Clases de sistemas de información") -> Clases de sistemas de información | C21: =IFERROR(__xludf.DUMMYFUNCTION("""COMPUTED_VALUE"""),"GIS") -> GIS | D21: x | E21: x | G21: x
A22: 5 | B22: =IFERROR(__xludf.DUMMYFUNCTION("""COMPUTED_VALUE"""),"Clases de sistemas de información") -> Clases de sistemas de información | C22: =IFERROR(__xludf.DUMMYFUNCTION("""COMPUTED_VALUE"""),"Conclusiones sobre clases de sistemas") -> Conclusiones sobre clases de sistemas | D22: x
A23: 6 | B23: =IFERROR(__xludf.DUMMYFUNCTION("""COMPUTED_VALUE"""),"Integración de sistemas") -> Integración de sistemas | C23: =IFERROR(__xludf.DUMMYFUNCTION("""COMPUTED_VALUE"""),"Definición de integración") -> Definición de integración | D23: x
A24: 7 | B24: =IFERROR(__xludf.DUMMYFUNCTION("""COMPUTED_VALUE"""),"Integración de sistemas") -> Integración de sistemas | C24: =IFERROR(__xludf.DUMMYFUNCTION("""COMPUTED_VALUE"""),"Beneficios de la integración") -> Beneficios de la integración | D24: x
A25: 8 | B25: =IFERROR(__xludf.DUMMYFUNCTION("""COMPUTED_VALUE"""),"Integración de sistemas") -> Integración de sistemas | C25: =IFERROR(__xludf.DUMMYFUNCTION("""COMPUTED_VALUE"""),"Ejemplos de integración") -> Ejemplos de integración | F25: x
A26: 9 | B26: =IFERROR(__xludf.DUMMYFUNCTION("""COMPUTED_VALUE"""),"Integración de sistemas") -> Integración de sistemas | C26: =IFERROR(__xludf.DUMMYFUNCTION("""COMPUTED_VALUE"""),"Herramientas de integración") -> Herramientas de integración | F26: x
A27: 10 | B27: =IFERROR(__xludf.DUMMYFUNCTION("""COMPUTED_VALUE"""),"Integración de sistemas") -> Integración de sistemas | C27: =IFERROR(__xludf.DUMMYFUNCTION("""COMPUTED_VALUE"""),"Desafíos en la integración") -> Desafíos en la integración | F27: x
A28: 11 | B28: =IFERROR(__xludf.DUMMYFUNCTION("""COMPUTED_VALUE"""),"Integración de sistemas") -> Integración de sistemas | C28: =IFERROR(__xludf.DUMMYFUNCTION("""COMPUTED_VALUE"""),"Impacto en la eficiencia organizacional") -> Impacto en la eficiencia organizacional | F28: x
A29: 12 | B29: =IFERROR(__xludf.DUMMYFUNCTION("""COMPUTED_VALUE"""),"Integración de sistemas") -> Integración de sistemas | C29: =IFERROR(__xludf.DUMMYFUNCTION("""COMPUTED_VALUE"""),"Futuro de la integración") -> Futuro de la integración | F29: x
B30: =IFERROR(__xludf.DUMMYFUNCTION("""COMPUTED_VALUE"""),"Arquitectura de sistemas") -> Arquitectura de sistemas | C30: =IFERROR(__xludf.DUMMYFUNCTION("""COMPUTED_VALUE"""),"Definición de arquitectura de sistemas") -> Definición de arquitectura de sistemas | G30: Sub total de tiempo | H30: =SUM(D16:G16) -> 85
A31: Marca con una x en recurso que planificas usar para impartir el conocimiento | B31: =IFERROR(__xludf.DUMMYFUNCTION("""COMPUTED_VALUE"""),"Arquitectura de sistemas") -> Arquitectura de sistemas | C31: =IFERROR(__xludf.DUMMYFUNCTION("""COMPUTED_VALUE"""),"Tipos de arquitectura") -> Tipos de arquitectura
A32: Otros : puedes modificarlo e indicar que recurso usarias por ejemplo simuladores
A34: Area de Habilidades
A35: Recordatorio
A36: Dentro de los 100 minutos de clase toma en cuenta incluir un tiempo para formar la habilidad del estudiante. Aprender haciendo.
A38: No. | B38: Tipo | C38: Ejercicio | D38: Practica | E38: Actividad | F38: Otros | G38: Cuestionario / Corto
B39: Tiempo Maximo | C39: 25 | D39: 25 | E39: 25 | F39: 25 | G39: 15
B40: Tiempo Planificado | C40: 5
B41: Ponderacion | C41: 0
B42: Competencia
A43: 1 | B43: integra sistemas de información organizacionales (ERP, SCM, CRM) utilizando tecnologías de información y comunicación con el fin de apoyar la transformación digital y mejorar la toma de decisiones estratégicas | C43: x
A44: 2 | B44: diseña soluciones de sistemas de información geográfica (GIS) y de inteligencia de negocios (BI) utilizando software especializado con el fin de optimizar la visualización y análisis de datos estratégicos | C44: x
A45: 3 | B45: valida metodologías de gestión del cambio y rediseño de procesos organizativos utilizando modelos de cambio organizativo y técnicas de reingeniería con el fin de garantizar la incorporación efectiva de las TIC | C45: x
A46: 4
A47: 5
A48: 6
...

Sheet S.10
A1: Curso | B1: ='Diseño Curricular'!B1 -> 786 - Sistemas Organizacionales y Gerenciales 1
A3: Semana | B3: 10
A5: Valores | B5: Planificación: Fomentar la planificación como valor clave para desarrollar, mantener y evolucionar sistemas de información de forma ordenada, sostenible y alineada con los objetivos de la organización.
A6: * Recuerda que las competencias tambien forman valores identifica el valor o valores que transmitiras esa semana
A8: Cronograma | B8: Para mantener la atención, es recomendable variar la dinámica de la clase cada cierto tiempo, integrando actividades como preguntas, ejercicios prácticos o discusiones en grupo. Esto es clave para la educación por competencias, ya que el aprendizaje debe ser activo y aplicado.
A11: Ponderacion | B11: =SUM(C41:G41) -> 0 | F11: Total de tiempo | H11: =H30+H50+H58 -> 100
A13: Area de conocimiento
C14: Tipo de Recurso | D14: Presentacion | E14: Video | F14: Lectura Explicativa | G14: Otros
C15: Tiempo Max | D15: 25 | E15: 10 | F15: 25 | G15: 25
C16: Tiempo Planificado | D16: 25 | E16: 10 | F16: 25 | G16: 25
A17: No. | B17: Tema | C17: Subtema
A18: 1 | B18: =IFERROR(__xludf.DUMMYFUNCTION("FILTER('Diseño Curricular'!D:D,'Diseño Curricular'!G:G=$B$3)"),"Arquitectura de sistemas") -> Arquitectura de sistemas | C18: =IFERROR(__xludf.DUMMYFUNCTION("FILTER('Diseño Curricular'!E:E,'Diseño Curricular'!G:G=$B$3)"),"Ejemplos de arquitecturas") -> Ejemplos de arquitecturas | D18: x | E18: x
A19: 2 | B19: =IFERROR(__xludf.DUMMYFUNCTION("""COMPUTED_VALUE"""),"Arquitectura de sistemas") -> Arquitectura de sistemas | C19: =IFERROR(__xludf.DUMMYFUNCTION("""COMPUTED_VALUE"""),"Herramientas para arquitecturas") -> Herramientas para arquitecturas | D19: x
A20: 3 | B20: =IFERROR(__xludf.DUMMYFUNCTION("""COMPUTED_VALUE"""),"Arquitectura de sistemas") -> Arquitectura de sistemas | C20: =IFERROR(__xludf.DUMMYFUNCTION("""COMPUTED_VALUE"""),"Impacto en la organización") -> Impacto en la organización | F20: x | G20: x
A21: 4 | B21: =IFERROR(__xludf.DUMMYFUNCTION("""COMPUTED_VALUE"""),"Arquitectura de sistemas") -> Arquitectura de sistemas | C21: =IFERROR(__xludf.DUMMYFUNCTION("""COMPUTED_VALUE"""),"Futuro de la arquitectura de sistemas") -> Futuro de la arquitectura de sistemas | F21: x
A22: 5 | B22: =IFERROR(__xludf.DUMMYFUNCTION("""COMPUTED_VALUE"""),"Arquitectura de sistemas") -> Arquitectura de sistemas | C22: =IFERROR(__xludf.DUMMYFUNCTION("""COMPUTED_VALUE"""),"Conclusiones sobre arquitectura") -> Conclusiones sobre arquitectura | D22: x
A23: 6 | B23: =IFERROR(__xludf.DUMMYFUNCTION("""COMPUTED_VALUE"""),"El ciclo de vida de un sistema") -> El ciclo de vida de un sistema | C23: =IFERROR(__xludf.DUMMYFUNCTION("""COMPUTED_VALUE"""),"Definición del ciclo de vida") -> Definición del ciclo de vida | F23: x
A24: 7 | B24: =IFERROR(__xludf.DUMMYFUNCTION("""COMPUTED_VALUE"""),"El ciclo de vida de un sistema") -> El ciclo de vida de un sistema | C24: =IFERROR(__xludf.DUMMYFUNCTION("""COMPUTED_VALUE"""),"Etapas del ciclo de vida") -> Etapas del ciclo de vida | F24: x
A25: 8 | B25: =IFERROR(__xludf.DUMMYFUNCTION("""COMPUTED_VALUE"""),"El ciclo de vida de un sistema") -> El ciclo de vida de un sistema | C25: =IFERROR(__xludf.DUMMYFUNCTION("""COMPUTED_VALUE"""),"Herramientas para el ciclo de vida") -> Herramientas para el ciclo de vida | D25: x
A26: 9 | B26: =IFERROR(__xludf.DUMMYFUNCTION("""COMPUTED_VALUE"""),"El ciclo de vida de un sistema") -> El ciclo de vida de un sistema | C26: =IFERROR(__xludf.DUMMYFUNCTION("""COMPUTED_VALUE"""),"Importancia del ciclo de vida") -> Importancia del ciclo de vida | D26: x
A27: 10 | B27: =IFERROR(__xludf.DUMMYFUNCTION("""COMPUTED_VALUE"""),"El ciclo de vida de un sistema") -> El ciclo de vida de un sistema | C27: =IFERROR(__xludf.DUMMYFUNCTION("""COMPUTED_VALUE"""),"Ejemplos de aplicación") -> Ejemplos de aplicación | F27: x
A28: 11 | B28: =IFERROR(__xludf.DUMMYFUNCTION("""COMPUTED_VALUE"""),"El ciclo de vida de un sistema") -> El ciclo de vida de un sistema | C28: =IFERROR(__xludf.DUMMYFUNCTION("""COMPUTED_VALUE"""),"Desafíos en el ciclo de vida") -> Desafíos en el ciclo de vida | E28: x
A29: 12 | B29: =IFERROR(__xludf.DUMMYFUNCTION("""COMPUTED_VALUE"""),"El ciclo de vida de un sistema") -> El ciclo de vida de un sistema | C29: =IFERROR(__xludf.DUMMYFUNCTION("""COMPUTED_VALUE"""),"Futuro del ciclo de vida") -> Futuro del ciclo de vida | D29: x | G29: x
G30: Sub total de tiempo | H30: =SUM(D16:G16) -> 85
A31: Marca con una x en recurso que planificas usar para impartir el conocimiento
A32: Otros : puedes modificarlo e indicar que recurso usarias por ejemplo simuladores
A34: Area de Habilidades
A35: Recordatorio
A36: Dentro de los 100 minutos de clase toma en cuenta incluir un tiempo para formar la habilidad del estudiante. Aprender haciendo.
A38: No. | B38: Tipo | C38: Ejercicio | D38: Practica | E38: Actividad | F38: Otros | G38: Cuestionario / Corto
B39: Tiempo Maximo | C39: 25 | D39: 25 | E39: 25 | F39: 25 | G39: 15
B40: Tiempo Planificado | C40: 5
B41: Ponderacion | C41: 0
B42: Competencia
A43: 1 | B43: revisa la evolución de los sistemas de información en la empresa mediante el análisis de casos históricos y actuales con el fin de identificar tendencias y áreas de mejora | C43: x
A44: 2 | B44: valida metodologías de gestión del cambio y rediseño de procesos organizativos utilizando modelos de cambio organizativo y técnicas de reingeniería con el fin de garantizar la incorporación efectiva de las TIC | C44: x
A45: 3 | B45: moviliza habilidades de pensamiento crítico y resolución de problemas utilizando estudios de caso empresariales con el fin de fortalecer la toma de decisiones en entornos organizacionales | C45: x
A46: 4
A47: 5
A48: 6
...

Sheet S.11
A1: Curso | B1: ='Diseño Curricular'!B1 -> 786 - Sistemas Organizacionales y Gerenciales 1
A3: Semana | B3: 11
A5: Valores | B5: Compromiso: Fomentar el compromiso como valor esencial en entornos educativos digitales, donde la motivación, la constancia y la participación activa son claves para el aprendizaje efectivo
A6: * Recuerda que las competencias tambien forman valores identifica el valor o valores que transmitiras esa semana
A8: Cronograma | B8: Para mantener la atención, es recomendable variar la dinámica de la clase cada cierto tiempo, integrando actividades como preguntas, ejercicios prácticos o discusiones en grupo. Esto es clave para la educación por competencias, ya que el aprendizaje debe ser activo y aplicado.
A11: Ponderacion | B11: =SUM(C38:G38) -> 0 | F11: Total de tiempo | H11: =H27+H47+H55 -> 100
A13: Area de conocimiento
C14: Tipo de Recurso | D14: Presentacion | E14: Video | F14: Lectura Explicativa | G14: Otros
C15: Tiempo Max | D15: 25 | E15: 10 | F15: 25 | G15: 25
C16: Tiempo Planificado | D16: 25 | E16: 10 | F16: 25 | G16: 25
A17: No. | B17: Tema | C17: Subtema
A18: 1 | B18: =IFERROR(__xludf.DUMMYFUNCTION("FILTER('Diseño Curricular'!D:D,'Diseño Curricular'!G:G=$B$3)"),"E-learning") -> E-learning | C18: =IFERROR(__xludf.DUMMYFUNCTION("FILTER('Diseño Curricular'!E:E,'Diseño Curricular'!G:G=$B$3)"),"Definición de e-learning") -> Definición de e-learning | D18: x | E18: x | G18: x
A19: 2 | B19: =IFERROR(__xludf.DUMMYFUNCTION("""COMPUTED_VALUE"""),"E-learning") -> E-learning | C19: =IFERROR(__xludf.DUMMYFUNCTION("""COMPUTED_VALUE"""),"Ventajas del e-learning") -> Ventajas del e-learning | D19: x
A20: 3 | B20: =IFERROR(__xludf.DUMMYFUNCTION("""COMPUTED_VALUE"""),"E-learning") -> E-learning | C20: =IFERROR(__xludf.DUMMYFUNCTION("""COMPUTED_VALUE"""),"Desafíos del e-learning") -> Desafíos del e-learning | D20: x | E20: x | F20: x
A21: 4 | B21: =IFERROR(__xludf.DUMMYFUNCTION("""COMPUTED_VALUE"""),"E-learning") -> E-learning | C21: =IFERROR(__xludf.DUMMYFUNCTION("""COMPUTED_VALUE"""),"Herramientas para e-learning") -> Herramientas para e-learning | F21: x
A22: 5 | B22: =IFERROR(__xludf.DUMMYFUNCTION("""COMPUTED_VALUE"""),"E-learning") -> E-learning | C22: =IFERROR(__xludf.DUMMYFUNCTION("""COMPUTED_VALUE"""),"Casos de éxito") -> Casos de éxito | D22: x | G22: x
A23: 6 | B23: =IFERROR(__xludf.DUMMYFUNCTION("""COMPUTED_VALUE"""),"E-learning") -> E-learning | C23: =IFERROR(__xludf.DUMMYFUNCTION("""COMPUTED_VALUE"""),"Futuro del e-learning") -> Futuro del e-learning | D23: x
A24: 7 | B24: =IFERROR(__xludf.DUMMYFUNCTION("""COMPUTED_VALUE"""),"E-learning") -> E-learning | C24: =IFERROR(__xludf.DUMMYFUNCTION("""COMPUTED_VALUE"""),"Conclusiones sobre e-learning") -> Conclusiones sobre e-learning | D24: x | G24: x
A25: 8 | B25: =IFERROR(__xludf.DUMMYFUNCTION("""COMPUTED_VALUE"""),"Gamificación en educación") -> Gamificación en educación | C25: =IFERROR(__xludf.DUMMYFUNCTION("""COMPUTED_VALUE"""),"Definición de plataformas educativas") -> Definición de plataformas educativas | D25: x | F25: x
A26: 9 | B26: =IFERROR(__xludf.DUMMYFUNCTION("""COMPUTED_VALUE"""),"Gamificación en educación") -> Gamificación en educación | C26: =IFERROR(__xludf.DUMMYFUNCTION("""COMPUTED_VALUE"""),"Ejemplos de plataformas educativas") -> Ejemplos de plataformas educativas | D26: x
B27: =IFERROR(__xludf.DUMMYFUNCTION("""COMPUTED_VALUE"""),"Gamificación en educación") -> Gamificación en educación | C27: =IFERROR(__xludf.DUMMYFUNCTION("""COMPUTED_VALUE"""),"Ventajas de las plataformas") -> Ventajas de las plataformas | G27: Sub total de tiempo | H27: =SUM(D16:G16) -> 85
A28: Marca con una x en recurso que planificas usar para impartir el conocimiento | B28: =IFERROR(__xludf.DUMMYFUNCTION("""COMPUTED_VALUE"""),"Gamificación en educación") -> Gamificación en educación | C28: =IFERROR(__xludf.DUMMYFUNCTION("""COMPUTED_VALUE"""),"Desafíos de las plataformas") -> Desafíos de las plataformas
A29: Otros : puedes modificarlo e indicar que recurso usarias por ejemplo simuladores | B29: =IFERROR(__xludf.DUMMYFUNCTION("""COMPUTED_VALUE"""),"Gamificación en educación") -> Gamificación en educación | C29: =IFERROR(__xludf.DUMMYFUNCTION("""COMPUTED_VALUE"""),"Futuro de las plataformas") -> Futuro de las plataformas
B30: =IFERROR(__xludf.DUMMYFUNCTION("""COMPUTED_VALUE"""),"Gamificación en educación") -> Gamificación en educación | C30: =IFERROR(__xludf.DUMMYFUNCTION("""COMPUTED_VALUE"""),"Casos de éxito") -> Casos de éxito
A31: Area de Habilidades | B31: =IFERROR(__xludf.DUMMYFUNCTION("""COMPUTED_VALUE"""),"Gamificación en educación") -> Gamificación en educación | C31: =IFERROR(__xludf.DUMMYFUNCTION("""COMPUTED_VALUE"""),"Conclusiones sobre plataformas") -> Conclusiones sobre plataformas
A32: Recordatorio
A33: Dentro de los 100 minutos de clase toma en cuenta incluir un tiempo para formar la habilidad del estudiante. Aprender haciendo.
A35: No. | B35: Tipo | C35: Ejercicio | D35: Practica | E35: Actividad | F35: Otros | G35: Cuestionario / Corto
B36: Tiempo Maximo | C36: 25 | D36: 25 | E36: 25 | F36: 25 | G36: 15
B37: Tiempo Planificado | C37: 5
B38: Ponderacion | C38: 0
B39: Competencia
A40: 1 | B40: contrasta ideas, soluciones y propuestas relacionadas con sistemas de información utilizando herramientas de comunicación efectiva con el fin de facilitar la colaboración y comprensión en la organización | C40: x
A41: 2 | B41: combina técnicas de trabajo en equipo y colaboración interdisciplinaria empleando metodologías ágiles de gestión de proyectos con el fin de fomentar la innovación y eficiencia organizacional | C41: x
A42: 3
A43: 4
A44: 5
A45: 6
A46: 7
G47: Sub total de tiempo | H47: =SUM(C37:G37) -> 5
...

Sheet S.12
A1: Curso | B1: ='Diseño Curricular'!B1 -> 786 - Sistemas Organizacionales y Gerenciales 1
A3: Semana | B3: 12
A5: Valores | B5: Compromiso: Fomentar el compromiso como valor esencial en entornos educativos digitales, donde la motivación, la constancia y la participación activa son claves para el aprendizaje efectivo
A6: * Recuerda que las competencias tambien forman valores identifica el valor o valores que transmitiras esa semana
A8: Cronograma | B8: Para mantener la atención, es recomendable variar la dinámica de la clase cada cierto tiempo, integrando actividades como preguntas, ejercicios prácticos o discusiones en grupo. Esto es clave para la educación por competencias, ya que el aprendizaje debe ser activo y aplicado.
A11: Ponderacion | B11: =SUM(C38:G38) -> 0 | F11: Total de tiempo | H11: =H27+H47+H55 -> 100
A13: Area de conocimiento
C14: Tipo de Recurso | D14: Presentacion | E14: Video | F14: Lectura Explicativa | G14: Otros
C15: Tiempo Max | D15: 25 | E15: 10 | F15: 25 | G15: 25
C16: Tiempo Planificado | D16: 25 | E16: 10 | F16: 25 | G16: 25
A17: No. | B17: Tema | C17: Subtema
A18: 1 | B18: =IFERROR(__xludf.DUMMYFUNCTION("FILTER('Diseño Curricular'!D:D,'Diseño Curricular'!G:G=$B$3)"),"#N/A") -> #N/A | C18: =IFERROR(__xludf.DUMMYFUNCTION("FILTER('Diseño Curricular'!E:E,'Diseño Curricular'!G:G=$B$3)"),"#N/A") -> #N/A | D18: x | E18: x | G18: x
A19: 2 | D19: x
A20: 3 | D20: x | E20: x | F20: x
A21: 4 | F21: x
A22: 5 | D22: x | G22: x
A23: 6 | D23: x
A24: 7 | D24: x | G24: x
A25: 8 | D25: x | F25: x
A26: 9 | D26: x
G27: Sub total de tiempo | H27: =SUM(D16:G16) -> 85
A28: Marca con una x en recurso que planificas usar para impartir el conocimiento
A29: Otros : puedes modificarlo e indicar que recurso usarias por ejemplo simuladores
A31: Area de Habilidades
A32: Recordatorio
A33: Dentro de los 100 minutos de clase toma en cuenta incluir un tiempo para formar la habilidad del estudiante. Aprender haciendo.
A35: No. | B35: Tipo | C35: Ejercicio | D35: Practica | E35: Actividad | F35: Otros | G35: Cuestionario / Corto
