Workbook

Sheet Metas
A1: Número | B1: Nombre de la Meta | C1: Descripcion de la Meta
A2: 1 | B2: Introducción al entorno del laboratorio. | C2: Presentar el programa del laboratorio, reglas de trabajo, formatos de entrega y medios de comunicación.
A3: 2 | B3: Familiarización con los conceptos básicos de modelación y simulación. | C3: Explicación sobre qué es la modelación y simulación, introducción a Simio y sus componentes generales, además de explorar la interfaz y librería estándar de Simio.
A4: 3 | B4: Comprender las distribuciones de probabilidad y sus aplicaciones. | C4: Explicación de qué son, para qué sirven, sus aplicaciones y cómo se relacionan con Simio. Además, análisis y ajuste de datos a una distribución.
A5: 4 | B5: Adquirir habilidades en el manejo de modelos de datos y en la aplicación y utilización de diversas tablas dentro de la herramienta Simio. | C5: Uso de data tables, rate tables, work schedule y sequence tables en la modelación.
A6: 5 | B6: Implementar gráficas, listas y colas en Simio. | C6: Explicación de cómo crear gráficas, listas y aplicar teoría de colas en Simio.
A7: 6 | B7: Aprender a usar combiner, separator e inventarios. | C7: Uso de los componentes combiner y separator, manipulación de inventarios, aplicación de un timer y políticas de reorden en Simio.
A8: 7 | B8: Dominar el modelado de procesos en Simio. | C8: Tipos de procesos y steps, junto con el estudio de balking y reneging en sistemas de simulación.
A9: 8 | B9: Introducción y aplicaciones de transportadores en Simio. | C9: Uso de workers, vehículos y lift trucks para modelos en Simio.
A10: 9 | B10: Introducción y aplicación de la librería extra de Simio. | C10: Explicación de componentes de la librería extra y cómo aplicarlos en modelos.
A11: 10 | B11: Modelado en 3D dentro de Simio. | C11: Explicación del modelado 3D funcional y ambiental, además de la creación y modificación de vistas.
A12: 11 | B12: Realizar análisis financiero en Simio. | C12: Introducción a conceptos financieros, cambio de divisas, creación de variables de centro de costos, y gastos por uso de servidores.
A13: 12 | B13: Analizar resultados en Simio. | C13: Uso de tablas pivote, generación de reportes y dashboards.
... A15: 14 | B15: Introducción y uso de la librería de flujos en Simio. | C15: Aplicación de componentes de la librería de flujos en modelos simulados.

Sheet Base del Diseño Curricular
A1: Numero de Mes | B1: Concepto Principal | C1: Semana | D1: Tema | E1: Numeral | F1: Sub Tema | G1: Nombre del Proyecto que abarca los conceptos impartidos
A2: 1 | B2: Introduccion a la Modelación y Simulación | C2: 1 | D2: Presentación de Laboratorio | E2: 1 | F2: Presentacion de programa de laboratorio | G2: Proyecto de modelación y simulación fase 1 | H2: 19/07 | I2: O
E3: 2 | F3: Datos generales
E4: 3 | F4: Reglas de trabajo
E5: 4 | F5: Formatos de entrega
E6: 5 | F6: Medios de comunicación
E7: 6
E8: 7
C9: 2 | D9: Introduccion a la Modelación y Simulación | E9: 1 | F9: ¿Qué es la modelación y simulación? | H9: 26/07 | I9: O
E10: 2 | F10: Explicación de que es Simio
E11: 3 | F11: Componentes generales y uso de Simio
E12: 4 | F12: Explicación de la interfaz de Simio
E13: 5 | F13: Explicación de la libreria estándar de Simio
E14: 6 | F14: Componentes generales
E15: 7
A16: 2 | B16: Herramientas y Técnicas para la Modelación y Simulación en Simio | C16: 3 | D16: Distribuciones de probabilidad | E16: 1 | F16: ¿Qué son las distribuciones de probabilidad? | H16: 45330 | I16: D
E17: 2 | F17: Para qué nos sirven
E18: 3 | F18: Aplicaciones de la distribuciones
E19: 4 | F19: Relación de las distribuciones con Simio
E20: 5 | F20: Análisis de datos
E21: 6 | F21: Como ajustar una serie de datos a una distribución
E22: 7 | F22: Ejemplo de ajustar una serie de datos a una distribución
C23: 4 | D23: Modelos basados en datos | E23: 1 | F23: Explicación y uso de data tables | H23: 45543 | I23: D
E24: 2 | F24: Explicación y uso de rate tables
E25: 3 | F25: Explicación y uso de work schedule
E26: 4 | F26: Explicación y uso de sequence tables
E27: 5
E28: 6
E29: 7
C30: 5 | D30: Utilización de gráficas, listas y colas | E30: 1 | F30: Explicación de las graficas de Simio | H30: 16/08 | I30: O
E31: 2 | F31: Definición y creación de listas en Simio
E32: 3 | F32: Teoría de colas
E33: 4 | F33: Aplicación de colas
E34: 5
E35: 6
E36: 7
C37: 6 | D37: Combiners, separadors, inventarios | E37: 1 | F37: Explicación y uso de Combiner | H37: 23/08 | I37: D
E38: 2 | F38: Explicación y uso Separator
E39: 3 | F39: Como manipular Inventarios en Simio
E40: 4 | F40: Como aplicar un Timer en Simio
...

Sheet DC con actividades
A1: Numero de Mes | B1: Concepto Principal | C1: Semana | D1: Tema | E1: Numeral | F1: Sub Tema | G1: Nombre del Proyecto que abarca los conceptos impartidos
A2: 1 | B2: Introduccion a la Modelación y Simulación | C2: 1 | D2: Presentación de Laboratorio | E2: 1 | F2: Presentacion de programa de laboratorio | H2: 19/07 | I2: O
E3: 2 | F3: Datos generales
E4: 3 | F4: Reglas de trabajo
E5: 4 | F5: Formatos de entrega
E6: 5 | F6: Medios de comunicación
E7: 6
E8: 7
C9: 2 | D9: Introduccion a la Modelación y Simulación | E9: 1 | F9: ¿Qué es la modelación y simulación? | G9: Tarea #1 | H9: 26/07 | I9: O
E10: 2 | F10: Explicación de que es Simio | G10: Corto #1
E11: 3 | F11: Componentes generales y uso de Simio | G11: Proyecto - Fase 1
E12: 4 | F12: Explicación de la interfaz de Simio
E13: 5 | F13: Explicación de la libreria estándar de Simio
E14: 6 | F14: Componentes generales
E15: 7
A16: 2 | B16: Herramientas y Técnicas para la Modelación y Simulación en Simio | C16: 3 | D16: Distribuciones de probabilidad | E16: 1 | F16: Que son las distribuciones de probabilidad | G16: Proyecto - Fase 1 | H16: 45330 | I16: D
E17: 2 | F17: Para que nos sirven
E18: 3 | F18: Aplicaciones de la distribuciones
E19: 4 | F19: Relación de las distribuciones con Simio
E20: 5 | F20: Análisis de datos
E21: 6 | F21: Como ajustar una serie de datos a una distribución
E22: 7 | F22: Ejemplo de ajustar una serie de datos a una distribución
C23: 4 | D23: Modelos basados en datos | E23: 1 | F23: Explicación y uso de data tables | G23: Proyecto - Fase 1 | H23: 45543 | I23: D
E24: 2 | F24: Explicación y uso de rate tables
E25: 3 | F25: Explicación y uso de work schedule
E26: 4 | F26: Explicación y uso de sequence tables
E27: 5
E28: 6
E29: 7
C30: 5 | D30: Utilización de gráficas, listas y colas | E30: 1 | F30: Explicación de las graficas de Simio | G30: Examen Corto #1 | H30: 16/08 | I30: O
E31: 2 | F31: Definición y creación de listas en Simio | G31: Proyecto - Fase 1
E32: 3 | F32: Teoría de colas
E33: 4 | F33: Aplicación de colas
E34: 5
E35: 6
E36: 7
C37: 6 | D37: Combiners, separadors, inventarios | E37: 1 | F37: Explicación y uso de Combiner | G37: Tarea #2 | H37: 23/08 | I37: D
E38: 2 | F38: Explicación y uso Separator | G38: Proyecto - Fase 1
E39: 3 | F39: Como manipular Inventarios en Simio
E40: 4 | F40: Como aplicar un Timer en Simio
...

Sheet Ejemplo
A1: Mes | B1: Enero
A2: Semana | B2: 1
A3: Concepto Principal | B3: Habilidades de Resolución de Problemas y Lógicas
A4: Tema | B4: Fundamentos de Algoritmos y Pensamiento Computacional
A6: Numeral | B6: Recurso | C6: Presentación | D6: Video | E6: Lectura | F6: Ejercicio | H6: Cuestionario | J6: Total de Tiempo
B7: Tiempo aproximado | C7: 15 | D7: 10 | E7: 10 | F7: 15 | G7: 5 | H7: 5 | I7: 15
B8: Tema
A9: 1 | B9: Pensamiento Algorítmico para la Resolución de Problemas Complejos | D9: X | E9: X | H9: X | J9: =if(D9="X",$D$7,0)+if(E9="X",$E$7,0)+if(F9="X",$F$7,0)+if(G9="X",$G$7,0)+if(H9="X",$H$7,0)+if(I9="X",$I$7,0) -> 25
A10: 2 | B10: Algoritmos Aplicados en Ciencias: Biología, Criptografía, Finanzas y Más | D10: X | F10: X | J10: =if(D10="X",$D$7,0)+if(E10="X",$E$7,0)+if(F10="X",$F$7,0)+if(G10="X",$G$7,0)+if(H10="X",$H$7,0)+if(I10="X",$I$7,0) -> 25
A11: 3 | B11: Comprendiendo los Sistemas Numéricos | D11: x | E11: x | H11: x | J11: =if(D11="X",$D$7,0)+if(E11="X",$E$7,0)+if(F11="X",$F$7,0)+if(G11="X",$G$7,0)+if(H11="X",$H$7,0)+if(I11="X",$I$7,0) -> 25
A12: 4 | B12: Creación de Algoritmos Interactivos con Scratch | D12: x | F12: x | J12: =if(D12="X",$D$7,0)+if(E12="X",$E$7,0)+if(F12="X",$F$7,0)+if(G12="X",$G$7,0)+if(H12="X",$H$7,0)+if(I12="X",$I$7,0) -> 25
A13: 5 | B13: Taller Práctico: Resolución de Problemas y Aplicación de Algoritmos | E13: x | F13: x | J13: =if(D13="X",$D$7,0)+if(E13="X",$E$7,0)+if(F13="X",$F$7,0)+if(G13="X",$G$7,0)+if(H13="X",$H$7,0)+if(I13="X",$I$7,0) -> 25
A14: 6 | B14: Evaluación de Conocimientos: Cuestionario de Algoritmos y Sistemas Numéricos | G14: x | I14: x | J14: =if(D14="X",$D$7,0)+if(E14="X",$E$7,0)+if(F14="X",$F$7,0)+if(G14="X",$G$7,0)+if(H14="X",$H$7,0)+if(I14="X",$I$7,0) -> 20
H15: Tiempo Total | J15: =SUM(J7:J14) -> 145

Sheet S1
A1: Mes | B1: Enero
A2: Semana | B2: 1
A3: Concepto Principal | B3: ='Base del Diseño Curricular'!B2 -> Introduccion a la Modelación y Simulación
A4: Tema | B4: ='Base del Diseño Curricular'!D2 -> Presentación de Laboratorio
A6: Numeral | B6: Recurso | C6: Presentación | D6: Video | E6: Lectura | F6: Ejercicio | H6: Cuestionario | J6: Total de Tiempo | K6: Ejercicio | L6: Cuestionario | M6: Total Ponderación
B7: Tiempo aproximado en minutos | C7: 15 | D7: 10 | E7: 10 | F7: 15 | G7: 5 | H7: 5 | I7: 15 | K7: Ponderación | L7: Ponderación
B8: Sub Tema
A9: 1 | B9: ='Base del Diseño Curricular'!F2 -> Presentacion de programa de laboratorio | C9: X | J9: =if(C9="X",$C$7,0)+if(D9="X",$D$7,0)+if(E9="X",$E$7,0)+if(F9="X",$F$7,0)+if(G9="X",$G$7,0)+if(H9="X",$H$7,0)+if(I9="X",$I$7,0) -> 15 | M9: =sum(K9:L9) -> 0
A10: 2 | B10: ='Base del Diseño Curricular'!F3 -> Datos generales | C10: X | J10: =IF(C10="X",$C$7,0)+IF(D10="X",$D$7,0)+IF(E10="X",$E$7,0)+IF(F10="X",$F$7,0)+IF(G10="X",$G$7,0)+IF(H10="X",$H$7,0)+IF(I10="X",$I$7,0) -> 15 | M10: =sum(K10:L10) -> 0
A11: 3 | B11: ='Base del Diseño Curricular'!F4 -> Reglas de trabajo | E11: X | J11: =if(C11="X",$C$7,0)+if(D11="X",$D$7,0)+if(E11="X",$E$7,0)+if(F11="X",$F$7,0)+if(G11="X",$G$7,0)+if(H11="X",$H$7,0)+if(I11="X",$I$7,0) -> 10 | M11: =sum(K11:L11) -> 0
A12: 4 | B12: ='Base del Diseño Curricular'!F5 -> Formatos de entrega | E12: X | J12: =IF(C12="X",$C$7,0)+IF(D12="X",$D$7,0)+IF(E12="X",$E$7,0)+IF(F12="X",$F$7,0)+IF(G12="X",$G$7,0)+IF(H12="X",$H$7,0)+IF(I12="X",$I$7,0) -> 10 | M12: =sum(K12:L12) -> 0
A13: 5 | B13: ='Base del Diseño Curricular'!F6 -> Medios de comunicación | C13: X | J13: =if(C13="X",$C$7,0)+if(D13="X",$D$7,0)+if(E13="X",$E$7,0)+if(F13="X",$F$7,0)+if(G13="X",$G$7,0)+if(H13="X",$H$7,0)+if(I13="X",$I$7,0) -> 15 | M13: =sum(K13:L13) -> 0
A14: 6 | B14: Introducción modelación y simulación | D14: X | I14: X | J14: =IF(C14="X",$C$7,0)+IF(D14="X",$D$7,0)+IF(E14="X",$E$7,0)+IF(F14="X",$F$7,0)+IF(G14="X",$G$7,0)+IF(H14="X",$H$7,0)+IF(I14="X",$I$7,0) -> 25 | L14: 1 | M14: =sum(K14:L14) -> 1
I15: Tiempo Total en minutos | J15: =SUM(J9:J14) -> 90 | L15: Total Ponderacion | M15: =sum(M9:M14) -> 1
A17: Notas:
A18: Colocar X en la casilla del recurso que se utilizara
A19: Se recomienda que la sumatoria de los minutos no supere los 120 minutos semanales

Sheet S2
A1: Mes | B1: Enero
A2: Semana | B2: 2
A3: Concepto Principal | B3: ='Base del Diseño Curricular'!B2 -> Introduccion a la Modelación y Simulación
A4: Tema | B4: ='Base del Diseño Curricular'!D9 -> Introduccion a la Modelación y Simulación
A6: Numeral | B6: Recurso | C6: Presentación | D6: Video | E6: Lectura | F6: Ejercicio | H6: Cuestionario | J6: Total de Tiempo | K6: Ejercicio | L6: Cuestionario | M6: Total Ponderación
B7: Tiempo aproximado en minutos | C7: 5 | D7: 10 | E7: 10 | F7: 15 | G7: 5 | H7: 5 | I7: 15 | K7: Ponderación | L7: Ponderación
B8: Sub Tema
A9: 1 | B9: ='Base del Diseño Curricular'!F9 -> ¿Qué es la modelación y simulación? | D9: X | J9: =if(C9="X",$C$7,0)+if(D9="X",$D$7,0)+if(E9="X",$E$7,0)+if(F9="X",$F$7,0)+if(G9="X",$G$7,0)+if(H9="X",$H$7,0)+if(I9="X",$I$7,0) -> 10 | M9: =sum(K9:L9) -> 0
A10: 2 | B10: ='Base del Diseño Curricular'!F10 -> Explicación de que es Simio | C10: X | J10: =IF(C10="X",$C$7,0)+IF(D10="X",$D$7,0)+IF(E10="X",$E$7,0)+IF(F10="X",$F$7,0)+IF(G10="X",$G$7,0)+IF(H10="X",$H$7,0)+IF(I10="X",$I$7,0) -> 5 | M10: =sum(K10:L10) -> 0
A11: 3 | B11: ='Base del Diseño Curricular'!F11 -> Componentes generales y uso de Simio | C11: X | E11: X | J11: =if(C11="X",$C$7,0)+if(D11="X",$D$7,0)+if(E11="X",$E$7,0)+if(F11="X",$F$7,0)+if(G11="X",$G$7,0)+if(H11="X",$H$7,0)+if(I11="X",$I$7,0) -> 15 | M11: =sum(K11:L11) -> 0
A12: 4 | B12: ='Base del Diseño Curricular'!F12 -> Explicación de la interfaz de Simio | C12: X | F12: X | J12: =IF(C12="X",$C$7,0)+IF(D12="X",$D$7,0)+IF(E12="X",$E$7,0)+IF(F12="X",$F$7,0)+IF(G12="X",$G$7,0)+IF(H12="X",$H$7,0)+IF(I12="X",$I$7,0) -> 20 | M12: =sum(K12:L12) -> 0
A13: 5 | B13: ='Base del Diseño Curricular'!F13 -> Explicación de la libreria estándar de Simio | C13: X | G13: X | J13: =if(C13="X",$C$7,0)+if(D13="X",$D$7,0)+if(E13="X",$E$7,0)+if(F13="X",$F$7,0)+if(G13="X",$G$7,0)+if(H13="X",$H$7,0)+if(I13="X",$I$7,0) -> 10 | M13: =sum(K13:L13) -> 0
A14: 6 | B14: ='Base del Diseño Curricular'!F14 -> Componentes generales | C14: X | F14: X | G14: X | I14: X | J14: =IF(C14="X",$C$7,0)+IF(D14="X",$D$7,0)+IF(E14="X",$E$7,0)+IF(F14="X",$F$7,0)+IF(G14="X",$G$7,0)+IF(H14="X",$H$7,0)+IF(I14="X",$I$7,0) -> 40 | L14: 2 | M14: =sum(K14:L14) -> 2
I15: Tiempo Total en minutos | J15: =SUM(J9:J14) -> 100 | L15: Total Ponderacion | M15: =sum(M9:M14) -> 2
A17: Notas:
A18: Colocar X en la casilla del recurso que se utilizara
A19: Se recomienda que la sumatoria de los minutos no supere los 120 minutos semanales

Sheet S3
A1: Mes | B1: Febrero
A2: Semana | B2: 3
A3: Concepto Principal | B3: ='Base del Diseño Curricular'!B16 -> Herramientas y Técnicas para la Modelación y Simulación en Simio
A4: Tema | B4: ='Base del Diseño Curricular'!D16 -> Distribuciones de probabilidad
A6: Numeral | B6: Recurso | C6: Presentación | E6: Video | F6: Lectura | G6: Ejercicio | I6: Cuestionario | K6: Total de Tiempo | L6: Ejercicio | M6: Cuestionario | N6: Total Ponderación
B7: Tiempo aproximado en minutos | C7: 10 | D7: 5 | E7: 5 | F7: 10 | G7: 30 | H7: 5 | I7: 5 | J7: 10 | L7: Ponderación | M7: Ponderación
B8: Sub Tema
A9: 1 | B9: ='Base del Diseño Curricular'!F16 -> ¿Qué son las distribuciones de probabilidad? | C9: X | E9: X | J9: X | K9: =if(C9="X",$C$7,0)+if(E9="X",$E$7,0)+if(D9="X",$D$7,0)+if(F9="X",$F$7,0)+if(G9="X",$G$7,0)+if(H9="X",$H$7,0)+if(I9="X",$I$7,0)+if(J9="X",$J$7,0) -> 25 | M9: 2 | N9: =sum(L9:M9) -> 2
A10: 2 | B10: ='Base del Diseño Curricular'!F17 -> Para qué nos sirven | D10: X | K10: =if(C10="X",$C$7,0)+if(E10="X",$E$7,0)+if(D10="X",$D$7,0)+if(F10="X",$F$7,0)+if(G10="X",$G$7,0)+if(H10="X",$H$7,0)+if(I10="X",$I$7,0)+if(J10="X",$J$7,0) -> 5 | N10: =sum(L10:M10) -> 0
A11: 3 | B11: ='Base del Diseño Curricular'!F18 -> Aplicaciones de la distribuciones | D11: X | K11: =if(C11="X",$C$7,0)+if(E11="X",$E$7,0)+if(D11="X",$D$7,0)+if(F11="X",$F$7,0)+if(G11="X",$G$7,0)+if(H11="X",$H$7,0)+if(I11="X",$I$7,0)+if(J11="X",$J$7,0) -> 5 | N11: =sum(L11:M11) -> 0
A12: 4 | B12: ='Base del Diseño Curricular'!F19 -> Relación de las distribuciones con Simio | D12: X | K12: =if(C12="X",$C$7,0)+if(E12="X",$E$7,0)+if(D12="X",$D$7,0)+if(F12="X",$F$7,0)+if(G12="X",$G$7,0)+if(H12="X",$H$7,0)+if(I12="X",$I$7,0)+if(J12="X",$J$7,0) -> 5 | N12: =sum(L12:M12) -> 0
A13: 5 | B13: ='Base del Diseño Curricular'!F20 -> Análisis de datos | D13: X | F13: X | H13: X | K13: =if(C13="X",$C$7,0)+if(E13="X",$E$7,0)+if(D13="X",$D$7,0)+if(F13="X",$F$7,0)+if(G13="X",$G$7,0)+if(H13="X",$H$7,0)+if(I13="X",$I$7,0)+if(J13="X",$J$7,0) -> 20 | L13: 2 | N13: =sum(L13:M13) -> 2
A14: 6 | B14: ='Base del Diseño Curricular'!F21 -> Como ajustar una serie de datos a una distribución | F14: X | K14: =if(C14="X",$C$7,0)+if(E14="X",$E$7,0)+if(D14="X",$D$7,0)+if(F14="X",$F$7,0)+if(G14="X",$G$7,0)+if(H14="X",$H$7,0)+if(I14="X",$I$7,0)+if(J14="X",$J$7,0) -> 10 | N14: =sum(L14:M14) -> 0
A15: 7 | B15: ='Base del Diseño Curricular'!F22 -> Ejemplo de ajustar una serie de datos a una distribución | G15: X | K15: =if(C15="X",$C$7,0)+if(E15="X",$E$7,0)+if(D15="X",$D$7,0)+if(F15="X",$F$7,0)+if(G15="X",$G$7,0)+if(H15="X",$H$7,0)+if(I15="X",$I$7,0)+if(J15="X",$J$7,0) -> 30
J16: Tiempo Total en minutos | K16: =SUM(K9:K15) -> 100 | M16: Total Ponderacion | N16: =sum(N9:N14) -> 4
A18: Notas:
A19: Colocar X en la casilla del recurso que se utilizara
A20: Se recomienda que la sumatoria de los minutos no supere los 120 minutos semanales

Sheet S4
A1: Mes | B1: Febrero
A2: Semana | B2: 4
A3: Concepto Principal | B3: ='Base del Diseño Curricular'!B16 -> Herramientas y Técnicas para la Modelación y Simulación en Simio
A4: Tema | B4: ='Base del Diseño Curricular'!D23 -> Modelos basados en datos
A6: Numeral | B6: Recurso | C6: Presentación | E6: Video | F6: Lectura | G6: Ejercicio | I6: Cuestionario | K6: Total de Tiempo | L6: Ejercicio | M6: Cuestionario | N6: Total Ponderación
B7: Tiempo aproximado en minutos | C7: 10 | D7: 5 | E7: 10 | F7: 10 | G7: 15 | H7: 5 | I7: 5 | J7: 15 | L7: Ponderación | M7: Ponderación
B8: Sub Tema
A9: 1 | B9: ='Base del Diseño Curricular'!F23 -> Explicación y uso de data tables | C9: X | G9: X | K9: =if(C9="X",$C$7,0)+if(E9="X",$E$7,0)+if(D9="X",$D$7,0)+if(F9="X",$F$7,0)+if(G9="X",$G$7,0)+if(H9="X",$H$7,0)+if(I9="X",$I$7,0)+if(J9="X",$J$7,0) -> 25 | N9: =sum(L9:M9) -> 0
A10: 2 | B10: ='Base del Diseño Curricular'!F24 -> Explicación y uso de rate tables | D10: X | F10: X | K10: =if(C10="X",$C$7,0)+if(E10="X",$E$7,0)+if(D10="X",$D$7,0)+if(F10="X",$F$7,0)+if(G10="X",$G$7,0)+if(H10="X",$H$7,0)+if(I10="X",$I$7,0)+if(J10="X",$J$7,0) -> 15 | N10: =sum(L10:M10) -> 0
A11: 3 | B11: ='Base del Diseño Curricular'!F25 -> Explicación y uso de work schedule | E11: X | G11: X | K11: =if(C11="X",$C$7,0)+if(E11="X",$E$7,0)+if(D11="X",$D$7,0)+if(F11="X",$F$7,0)+if(G11="X",$G$7,0)+if(H11="X",$H$7,0)+if(I11="X",$I$7,0)+if(J11="X",$J$7,0) -> 25 | N11: =sum(L11:M11) -> 0
A12: 4 | B12: ='Base del Diseño Curricular'!F26 -> Explicación y uso de sequence tables | C12: X | F12: X | J12: X | K12: =if(C12="X",$C$7,0)+if(E12="X",$E$7,0)+if(D12="X",$D$7,0)+if(F12="X",$F$7,0)+if(G12="X",$G$7,0)+if(H12="X",$H$7,0)+if(I12="X",$I$7,0)+if(J12="X",$J$7,0) -> 35 | M12: 2 | N12: =sum(L12:M12) -> 2
A13: 5 | K13: =if(C13="X",$C$7,0)+if(E13="X",$E$7,0)+if(D13="X",$D$7,0)+if(F13="X",$F$7,0)+if(G13="X",$G$7,0)+if(H13="X",$H$7,0)+if(I13="X",$I$7,0)+if(J13="X",$J$7,0) -> 0 | N13: =sum(L13:M13) -> 0
A14: 6 | K14: =if(C14="X",$C$7,0)+if(E14="X",$E$7,0)+if(D14="X",$D$7,0)+if(F14="X",$F$7,0)+if(G14="X",$G$7,0)+if(H14="X",$H$7,0)+if(I14="X",$I$7,0)+if(J14="X",$J$7,0) -> 0 | N14: =sum(L14:M14) -> 0
A15: 7 | K15: =if(C15="X",$C$7,0)+if(E15="X",$E$7,0)+if(D15="X",$D$7,0)+if(F15="X",$F$7,0)+if(G15="X",$G$7,0)+if(H15="X",$H$7,0)+if(I15="X",$I$7,0)+if(J15="X",$J$7,0) -> 0
J16: Tiempo Total en minutos | K16: =SUM(K9:K15) -> 100 | M16: Total Ponderacion | N16: =sum(N9:N14) -> 2
A18: Notas:
A19: Colocar X en la casilla del recurso que se utilizara
A20: Se recomienda que la sumatoria de los minutos no supere los 120 minutos semanales

Sheet S5
A1: Mes | B1: Febrero
A2: Semana | B2: 5
A3: Concepto Principal | B3: ='Base del Diseño Curricular'!B16 -> Herramientas y Técnicas para la Modelación y Simulación en Simio
A4: Tema | B4: ='Base del Diseño Curricular'!D30 -> Utilización de gráficas, listas y colas
A6: Numeral | B6: Recurso | C6: Presentación | D6: Video | E6: Lectura | F6: Ejercicio | H6: Cuestionario | J6: Total de Tiempo | K6: Ejercicio | L6: Cuestionario | M6: Total Ponderación
B7: Tiempo aproximado en minutos | C7: 15 | D7: 10 | E7: 10 | F7: 15 | G7: 5 | H7: 5 | I7: 15 | K7: Ponderación | L7: Ponderación
B8: Sub Tema
A9: 1 | B9: ='Base del Diseño Curricular'!F30 -> Explicación de las graficas de Simio | C9: X | J9: =if(C9="X",$C$7,0)+if(D9="X",$D$7,0)+if(E9="X",$E$7,0)+if(F9="X",$F$7,0)+if(G9="X",$G$7,0)+if(H9="X",$H$7,0)+if(I9="X",$I$7,0) -> 15 | M9: =sum(K9:L9) -> 0
A10: 2 | B10: ='Base del Diseño Curricular'!F31 -> Definición y creación de listas en Simio | C10: X | F10: x | J10: =IF(C10="X",$C$7,0)+IF(D10="X",$D$7,0)+IF(E10="X",$E$7,0)+IF(F10="X",$F$7,0)+IF(G10="X",$G$7,0)+IF(H10="X",$H$7,0)+IF(I10="X",$I$7,0) -> 30 | M10: =sum(K10:L10) -> 0
A11: 3 | B11: ='Base del Diseño Curricular'!F32 -> Teoría de colas | E11: X | I11: X | J11: =if(C11="X",$C$7,0)+if(D11="X",$D$7,0)+if(E11="X",$E$7,0)+if(F11="X",$F$7,0)+if(G11="X",$G$7,0)+if(H11="X",$H$7,0)+if(I11="X",$I$7,0) -> 25 | L11: 2 | M11: =sum(K11:L11) -> 2
A12: 4 | B12: ='Base del Diseño Curricular'!F33 -> Aplicación de colas | D12: X | F12: x | G12: X | J12: =IF(C12="X",$C$7,0)+IF(D12="X",$D$7,0)+IF(E12="X",$E$7,0)+IF(F12="X",$F$7,0)+IF(G12="X",$G$7,0)+IF(H12="X",$H$7,0)+IF(I12="X",$I$7,0) -> 30 | M12: =sum(K12:L12) -> 0
A13: 5 | B13: ='Base del Diseño Curricular'!F34 | J13: =if(C13="X",$C$7,0)+if(D13="X",$D$7,0)+if(E13="X",$E$7,0)+if(F13="X",$F$7,0)+if(G13="X",$G$7,0)+if(H13="X",$H$7,0)+if(I13="X",$I$7,0) -> 0 | M13: =sum(K13:L13) -> 0
A14: 6 | B14: ='Base del Diseño Curricular'!F35 | J14: =IF(C14="X",$C$7,0)+IF(D14="X",$D$7,0)+IF(E14="X",$E$7,0)+IF(F14="X",$F$7,0)+IF(G14="X",$G$7,0)+IF(H14="X",$H$7,0)+IF(I14="X",$I$7,0) -> 0 | M14: =sum(K14:L14) -> 0
I15: Tiempo Total en minutos | J15: =SUM(J9:J14) -> 100 | L15: Total Ponderacion | M15: =sum(M9:M14) -> 2
A17: Notas:
A18: Colocar X en la casilla del recurso que se utilizara
A19: Se recomienda que la sumatoria de los minutos no supere los 120 minutos semanales

Sheet S6
A1: Mes | B1: Febrero
A2: Semana | B2: 6
A3: Concepto Principal | B3: ='Base del Diseño Curricular'!B16 -> Herramientas y Técnicas para la Modelación y Simulación en Simio
A4: Tema | B4: ='Base del Diseño Curricular'!D37 -> Combiners, separadors, inventarios
A6: Numeral | B6: Recurso | C6: Presentación | E6: Video | F6: Lectura | G6: Ejercicio | I6: Cuestionario | K6: Total de Tiempo | L6: Ejercicio | M6: Cuestionario | N6: Total Ponderación
B7: Tiempo aproximado en minutos | C7: 10 | D7: 5 | E7: 10 | F7: 10 | G7: 15 | H7: 5 | I7: 5 | J7: 15 | L7: Ponderación | M7: Ponderación
B8: Sub Tema
A9: 1 | B9: ='Base del Diseño Curricular'!F37 -> Explicación y uso de Combiner | D9: X | K9: =if(C9="X",$C$7,0)+if(E9="X",$E$7,0)+if(D9="X",$D$7,0)+if(F9="X",$F$7,0)+if(G9="X",$G$7,0)+if(H9="X",$H$7,0)+if(I9="X",$I$7,0)+if(J9="X",$J$7,0) -> 5 | N9: =sum(L9:M9) -> 0
A10: 2 | B10: ='Base del Diseño Curricular'!F38 -> Explicación y uso Separator | D10: X | E10: X | G10: X | K10: =if(C10="X",$C$7,0)+if(E10="X",$E$7,0)+if(D10="X",$D$7,0)+if(F10="X",$F$7,0)+if(G10="X",$G$7,0)+if(H10="X",$H$7,0)+if(I10="X",$I$7,0)+if(J10="X",$J$7,0) -> 30 | N10: =sum(L10:M10) -> 0
A11: 3 | B11: ='Base del Diseño Curricular'!F39 -> Como manipular Inventarios en Simio | D11: X | K11: =if(C11="X",$C$7,0)+if(E11="X",$E$7,0)+if(D11="X",$D$7,0)+if(F11="X",$F$7,0)+if(G11="X",$G$7,0)+if(H11="X",$H$7,0)+if(I11="X",$I$7,0)+if(J11="X",$J$7,0) -> 5 | N11: =sum(L11:M11) -> 0
A12: 4 | B12: ='Base del Diseño Curricular'!F40 -> Como aplicar un Timer en Simio | D12: X | K12: =if(C12="X",$C$7,0)+if(E12="X",$E$7,0)+if(D12="X",$D$7,0)+if(F12="X",$F$7,0)+if(G12="X",$G$7,0)+if(H12="X",$H$7,0)+if(I12="X",$I$7,0)+if(J12="X",$J$7,0) -> 5 | N12: =sum(L12:M12) -> 0
A13: 5 | B13: ='Base del Diseño Curricular'!F41 -> Política mínimo y máximo | D13: X | K13: =if(C13="X",$C$7,0)+if(E13="X",$E$7,0)+if(D13="X",$D$7,0)+if(F13="X",$F$7,0)+if(G13="X",$G$7,0)+if(H13="X",$H$7,0)+if(I13="X",$I$7,0)+if(J13="X",$J$7,0) -> 5 | N13: =sum(L13:M13) -> 0
A14: 6 | B14: ='Base del Diseño Curricular'!F42 -> Política de punto de reorden | D14: X | F14: X | G14: X | H14: X | J14: X | K14: =if(C14="X",$C$7,0)+if(E14="X",$E$7,0)+if(D14="X",$D$7,0)+if(F14="X",$F$7,0)+if(G14="X",$G$7,0)+if(H14="X",$H$7,0)+if(I14="X",$I$7,0)+if(J14="X",$J$7,0) -> 50 | M14: 2 | N14: =sum(L14:M14) -> 2
A15: 7 | K15: =if(C15="X",$C$7,0)+if(E15="X",$E$7,0)+if(D15="X",$D$7,0)+if(F15="X",$F$7,0)+if(G15="X",$G$7,0)+if(H15="X",$H$7,0)+if(I15="X",$I$7,0)+if(J15="X",$J$7,0) -> 0
J16: Tiempo Total en minutos | K16: =SUM(K9:K15) -> 100 | M16: Total Ponderacion | N16: =sum(N9:N14) -> 2
A18: Notas:
A19: Colocar X en la casilla del recurso que se utilizara
A20: Se recomienda que la sumatoria de los minutos no supere los 120 minutos semanales

Sheet S7
A1: Mes | B1: Marzo
A2: Semana | B2: 7
A3: Concepto Principal | B3: ='Base del Diseño Curricular'!B44 -> Procesos y Modelado Avanzado en Simio
A4: Tema | B4: ='Base del Diseño Curricular'!D44 -> Modelado de procesos
A6: Numeral | B6: Recurso | C6: Presentación | E6: Video | F6: Lectura | G6: Ejercicio | I6: Cuestionario | K6: Total de Tiempo | L6: Ejercicio | M6: Cuestionario | N6: Total Ponderación
B7: Tiempo aproximado en minutos | C7: 15 | D7: 5 | E7: 15 | F7: 15 | G7: 20 | H7: 10 | I7: 5 | J7: 15 | L7: Ponderación | M7: Ponderación
B8: Sub Tema
A9: 1 | B9: ='Base del Diseño Curricular'!F44 -> Tipos y usos de procesos | D9: X | E9: X | G9: X | J9: X | K9: =if(C9="X",$C$7,0)+if(E9="X",$E$7,0)+if(D9="X",$D$7,0)+if(F9="X",$F$7,0)+if(G9="X",$G$7,0)+if(H9="X",$H$7,0)+if(I9="X",$I$7,0)+if(J9="X",$J$7,0) -> 55 | M9: 2 | N9: =sum(L9:M9) -> 2
A10: 2 | B10: ='Base del Diseño Curricular'!F45 -> Tipos y usos de steps | D10: X | F10: X | H10: X | K10: =if(C10="X",$C$7,0)+if(E10="X",$E$7,0)+if(D10="X",$D$7,0)+if(F10="X",$F$7,0)+if(G10="X",$G$7,0)+if(H10="X",$H$7,0)+if(I10="X",$I$7,0)+if(J10="X",$J$7,0) -> 30 | N10: =sum(L10:M10) -> 0
A11: 3 | B11: ='Base del Diseño Curricular'!F46 -> Balking y reneging | D11: X | H11: X | K11: =if(C11="X",$C$7,0)+if(E11="X",$E$7,0)+if(D11="X",$D$7,0)+if(F11="X",$F$7,0)+if(G11="X",$G$7,0)+if(H11="X",$H$7,0)+if(I11="X",$I$7,0)+if(J11="X",$J$7,0) -> 15 | N11: =sum(L11:M11) -> 0
A12: 4 | K12: =if(C12="X",$C$7,0)+if(E12="X",$E$7,0)+if(D12="X",$D$7,0)+if(F12="X",$F$7,0)+if(G12="X",$G$7,0)+if(H12="X",$H$7,0)+if(I12="X",$I$7,0)+if(J12="X",$J$7,0) -> 0 | N12: =sum(L12:M12) -> 0
A13: 5 | K13: =if(C13="X",$C$7,0)+if(E13="X",$E$7,0)+if(D13="X",$D$7,0)+if(F13="X",$F$7,0)+if(G13="X",$G$7,0)+if(H13="X",$H$7,0)+if(I13="X",$I$7,0)+if(J13="X",$J$7,0) -> 0 | N13: =sum(L13:M13) -> 0
A14: 6 | K14: =if(C14="X",$C$7,0)+if(E14="X",$E$7,0)+if(D14="X",$D$7,0)+if(F14="X",$F$7,0)+if(G14="X",$G$7,0)+if(H14="X",$H$7,0)+if(I14="X",$I$7,0)+if(J14="X",$J$7,0) -> 0 | N14: =sum(L14:M14) -> 0
A15: 7 | K15: =if(C15="X",$C$7,0)+if(E15="X",$E$7,0)+if(D15="X",$D$7,0)+if(F15="X",$F$7,0)+if(G15="X",$G$7,0)+if(H15="X",$H$7,0)+if(I15="X",$I$7,0)+if(J15="X",$J$7,0) -> 0
J16: Tiempo Total en minutos | K16: =SUM(K9:K15) -> 100 | M16: Total Ponderacion | N16: =sum(N9:N14) -> 2
A18: Notas:
A19: Colocar X en la casilla del recurso que se utilizara
A20: Se recomienda que la sumatoria de los minutos no supere los 120 minutos semanales

Sheet S8
A1: Mes | B1: Marzo
A2: Semana | B2: 8
A3: Concepto Principal | B3: ='Base del Diseño Curricular'!B44 -> Procesos y Modelado Avanzado en Simio
A4: Tema | B4: ='Base del Diseño Curricular'!D51 -> Tranportadores
A6: Numeral | B6: Recurso | C6: Presentación | E6: Video | F6: Lectura | G6: Ejercicio | I6: Cuestionario | K6: Total de Tiempo | L6: Ejercicio | M6: Cuestionario | N6: Total Ponderación
B7: Tiempo aproximado en minutos | C7: 5 | D7: 10 | E7: 10 | F7: 10 | G7: 20 | H7: 15 | I7: 5 | J7: 15 | L7: Ponderación | M7: Ponderación
B8: Sub Tema
A9: 1 | B9: ='Base del Diseño Curricular'!F51 -> Como generar Workers y usarlos en nuestos modelos en Simio | C9: X | F9: X | K9: =if(C9="X",$C$7,0)+if(E9="X",$E$7,0)+if(D9="X",$D$7,0)+if(F9="X",$F$7,0)+if(G9="X",$G$7,0)+if(H9="X",$H$7,0)+if(I9="X",$I$7,0)+if(J9="X",$J$7,0) -> 15 | N9: =sum(L9:M9) -> 0
A10: 2 | B10: ='Base del Diseño Curricular'!F52 -> Como generar Vehiculos y aplicarlos en nuestros modelos en Simio | D10: X | E10: X | G10: X | J10: X | K10: =if(C10="X",$C$7,0)+if(E10="X",$E$7,0)+if(D10="X",$D$7,0)+if(F10="X",$F$7,0)+if(G10="X",$G$7,0)+if(H10="X",$H$7,0)+if(I10="X",$I$7,0)+if(J10="X",$J$7,0) -> 55 | M10: 2 | N10: =sum(L10:M10) -> 2
A11: 3 | B11: ='Base del Diseño Curricular'!F53 -> Que es y como funcionan los Lift trucks | C11: X | F11: X | H11: X | K11: =if(C11="X",$C$7,0)+if(E11="X",$E$7,0)+if(D11="X",$D$7,0)+if(F11="X",$F$7,0)+if(G11="X",$G$7,0)+if(H11="X",$H$7,0)+if(I11="X",$I$7,0)+if(J11="X",$J$7,0) -> 30 | N11: =sum(L11:M11) -> 0
A12: 4 | K12: =if(C12="X",$C$7,0)+if(E12="X",$E$7,0)+if(D12="X",$D$7,0)+if(F12="X",$F$7,0)+if(G12="X",$G$7,0)+if(H12="X",$H$7,0)+if(I12="X",$I$7,0)+if(J12="X",$J$7,0) -> 0 | N12: =sum(L12:M12) -> 0
A13: 5 | K13: =if(C13="X",$C$7,0)+if(E13="X",$E$7,0)+if(D13="X",$D$7,0)+if(F13="X",$F$7,0)+if(G13="X",$G$7,0)+if(H13="X",$H$7,0)+if(I13="X",$I$7,0)+if(J13="X",$J$7,0) -> 0 | N13: =sum(L13:M13) -> 0
A14: 6 | K14: =if(C14="X",$C$7,0)+if(E14="X",$E$7,0)+if(D14="X",$D$7,0)+if(F14="X",$F$7,0)+if(G14="X",$G$7,0)+if(H14="X",$H$7,0)+if(I14="X",$I$7,0)+if(J14="X",$J$7,0) -> 0 | N14: =sum(L14:M14) -> 0
A15: 7 | K15: =if(C15="X",$C$7,0)+if(E15="X",$E$7,0)+if(D15="X",$D$7,0)+if(F15="X",$F$7,0)+if(G15="X",$G$7,0)+if(H15="X",$H$7,0)+if(I15="X",$I$7,0)+if(J15="X",$J$7,0) -> 0
J16: Tiempo Total en minutos | K16: =SUM(K9:K15) -> 100 | M16: Total Ponderacion | N16: =sum(N9:N14) -> 2
A18: Notas:
A19: Colocar X en la casilla del recurso que se utilizara
A20: Se recomienda que la sumatoria de los minutos no supere los 120 minutos semanales

Sheet S9
A1: Mes | B1: Marzo
A2: Semana | B2: 9
A3: Concepto Principal | B3: ='Base del Diseño Curricular'!B44 -> Procesos y Modelado Avanzado en Simio
A4: Tema | B4: ='Base del Diseño Curricular'!D58 -> Libreria extra de Simio
A6: Numeral | B6: Recurso | C6: Presentación | D6: Video | E6: Lectura | F6: Ejercicio | H6: Cuestionario | J6: Total de Tiempo | K6: Ejercicio | L6: Cuestionario | M6: Total Ponderación
B7: Tiempo aproximado en minutos | C7: 5 | D7: 15 | E7: 10 | F7: 30 | G7: 10 | H7: 5 | I7: 20 | K7: Ponderación | L7: Ponderación
B8: Sub Tema
A9: 1 | B9: ='Base del Diseño Curricular'!F58 -> Introduccion a libreria extra de Simio | C9: X | D9: X | G9: X | J9: =if(C9="X",$C$7,0)+if(D9="X",$D$7,0)+if(E9="X",$E$7,0)+if(F9="X",$F$7,0)+if(G9="X",$G$7,0)+if(H9="X",$H$7,0)+if(I9="X",$I$7,0) -> 30 | M9: =sum(K9:L9) -> 0
A10: 2 | B10: ='Base del Diseño Curricular'!F59 -> Explicacion de los componentes de la libreria extra | C10: X | E10: X | I10: X | J10: =IF(C10="X",$C$7,0)+IF(D10="X",$D$7,0)+IF(E10="X",$E$7,0)+IF(F10="X",$F$7,0)+IF(G10="X",$G$7,0)+IF(H10="X",$H$7,0)+IF(I10="X",$I$7,0) -> 35 | L10: 2 | M10: =sum(K10:L10) -> 2
A11: 3 | B11: ='Base del Diseño Curricular'!F60 -> Como aplicar los componentes de la libreria extra | C11: X | F11: X | J11: =if(C11="X",$C$7,0)+if(D11="X",$D$7,0)+if(E11="X",$E$7,0)+if(F11="X",$F$7,0)+if(G11="X",$G$7,0)+if(H11="X",$H$7,0)+if(I11="X",$I$7,0) -> 35 | M11: =sum(K11:L11) -> 0
A12: 4 | B12: ='Base del Diseño Curricular'!F61 | J12: =IF(C12="X",$C$7,0)+IF(D12="X",$D$7,0)+IF(E12="X",$E$7,0)+IF(F12="X",$F$7,0)+IF(G12="X",$G$7,0)+IF(H12="X",$H$7,0)+IF(I12="X",$I$7,0) -> 0 | M12: =sum(K12:L12) -> 0
A13: 5 | B13: ='Base del Diseño Curricular'!F62 | J13: =if(C13="X",$C$7,0)+if(D13="X",$D$7,0)+if(E13="X",$E$7,0)+if(F13="X",$F$7,0)+if(G13="X",$G$7,0)+if(H13="X",$H$7,0)+if(I13="X",$I$7,0) -> 0 | M13: =sum(K13:L13) -> 0
A14: 6 | B14: ='Base del Diseño Curricular'!F63 | J14: =IF(C14="X",$C$7,0)+IF(D14="X",$D$7,0)+IF(E14="X",$E$7,0)+IF(F14="X",$F$7,0)+IF(G14="X",$G$7,0)+IF(H14="X",$H$7,0)+IF(I14="X",$I$7,0) -> 0 | M14: =sum(K14:L14) -> 0
I15: Tiempo Total en minutos | J15: =SUM(J9:J14) -> 100 | L15: Total Ponderacion | M15: =sum(M9:M14) -> 2
A17: Notas:
A18: Colocar X en la casilla del recurso que se utilizara
A19: Se recomienda que la sumatoria de los minutos no supere los 120 minutos semanales

Sheet S10
A1: Mes | B1: Marzo
A2: Semana | B2: 10
A3: Concepto Principal | B3: ='Base del Diseño Curricular'!D65 -> Como modelar en 3D usando Simio
A4: Tema | B4: ='Base del Diseño Curricular'!B44 -> Procesos y Modelado Avanzado en Simio
A6: Numeral | B6: Recurso | C6: Presentación | D6: Video | E6: Lectura | F6: Ejercicio | H6: Cuestionario | J6: Total de Tiempo | K6: Ejercicio | L6: Cuestionario | M6: Total Ponderación
B7: Tiempo aproximado en minutos | C7: 5 | D7: 10 | E7: 20 | F7: 20 | G7: 5 | H7: 5 | I7: 15 | K7: Ponderación | L7: Ponderación
B8: Sub Tema
A9: 1 | B9: ='Base del Diseño Curricular'!F65 -> Explicacion de que es el modelado 3D | C9: X | J9: =if(C9="X",$C$7,0)+if(D9="X",$D$7,0)+if(E9="X",$E$7,0)+if(F9="X",$F$7,0)+if(G9="X",$G$7,0)+if(H9="X",$H$7,0)+if(I9="X",$I$7,0) -> 5 | M9: =sum(K9:L9) -> 0
A10: 2 | B10: ='Base del Diseño Curricular'!F66 -> Para que sirve el modelado 3D | C10: X | J10: =IF(C10="X",$C$7,0)+IF(D10="X",$D$7,0)+IF(E10="X",$E$7,0)+IF(F10="X",$F$7,0)+IF(G10="X",$G$7,0)+IF(H10="X",$H$7,0)+IF(I10="X",$I$7,0) -> 5 | M10: =sum(K10:L10) -> 0
A11: 3 | B11: ='Base del Diseño Curricular'!F67 -> Modelado 3D funcional | C11: X | J11: =if(C11="X",$C$7,0)+if(D11="X",$D$7,0)+if(E11="X",$E$7,0)+if(F11="X",$F$7,0)+if(G11="X",$G$7,0)+if(H11="X",$H$7,0)+if(I11="X",$I$7,0) -> 5 | M11: =sum(K11:L11) -> 0
A12: 4 | B12: ='Base del Diseño Curricular'!F68 -> Modelado 3D ambiental | C12: X | D12: X | J12: =IF(C12="X",$C$7,0)+IF(D12="X",$D$7,0)+IF(E12="X",$E$7,0)+IF(F12="X",$F$7,0)+IF(G12="X",$G$7,0)+IF(H12="X",$H$7,0)+IF(I12="X",$I$7,0) -> 15 | M12: =sum(K12:L12) -> 0
A13: 5 | B13: ='Base del Diseño Curricular'!F69 -> Como descargar mas modelos en 3D | C13: X | E13: X | G13: X | J13: =if(C13="X",$C$7,0)+if(D13="X",$D$7,0)+if(E13="X",$E$7,0)+if(F13="X",$F$7,0)+if(G13="X",$G$7,0)+if(H13="X",$H$7,0)+if(I13="X",$I$7,0) -> 30 | M13: =sum(K13:L13) -> 0
A14: 6 | B14: ='Base del Diseño Curricular'!F70 -> Creación, modificación de vistas | C14: X | F14: X | I14: X | J14: =IF(C14="X",$C$7,0)+IF(D14="X",$D$7,0)+IF(E14="X",$E$7,0)+IF(F14="X",$F$7,0)+IF(G14="X",$G$7,0)+IF(H14="X",$H$7,0)+IF(I14="X",$I$7,0) -> 40 | K14: 2 | L14: 2 | M14: =sum(K14:L14) -> 4
I15: Tiempo Total en minutos | J15: =SUM(J9:J14) -> 100 | L15: Total Ponderacion | M15: =sum(M9:M14) -> 4
A17: Notas:
A18: Colocar X en la casilla del recurso que se utilizara
A19: Se recomienda que la sumatoria de los minutos no supere los 120 minutos semanales

Sheet S11
A1: Mes | B1: Abril
A2: Semana | B2: 11
A3: Concepto Principal | B3: ='Base del Diseño Curricular'!B72 -> Análisis Financiero y Experimentos Avanzados en Simio
A4: Tema | B4: ='Base del Diseño Curricular'!D72 -> Como realizar finanzas en Simio
A6: Numeral | B6: Recurso | C6: Presentación | D6: Video | E6: Lectura | F6: Ejercicio | H6: Cuestionario | J6: Total de Tiempo | K6: Ejercicio | L6: Cuestionario | M6: Total Ponderación
B7: Tiempo aproximado en minutos | C7: 5 | D7: 15 | E7: 15 | F7: 15 | G7: 5 | H7: 5 | I7: 15 | K7: Ponderación | L7: Ponderación
B8: Sub Tema
A9: 1 | B9: ='Base del Diseño Curricular'!F72 -> Introduccion a finanzas | C9: X | D9: X | I9: X | J9: =if(C9="X",$C$7,0)+if(D9="X",$D$7,0)+if(E9="X",$E$7,0)+if(F9="X",$F$7,0)+if(G9="X",$G$7,0)+if(H9="X",$H$7,0)+if(I9="X",$I$7,0) -> 35 | L9: 2 | M9: =sum(K9:L9) -> 2
A10: 2 | B10: ='Base del Diseño Curricular'!F73 -> Como realizar el cambio de divisas | C10: X | J10: =IF(C10="X",$C$7,0)+IF(D10="X",$D$7,0)+IF(E10="X",$E$7,0)+IF(F10="X",$F$7,0)+IF(G10="X",$G$7,0)+IF(H10="X",$H$7,0)+IF(I10="X",$I$7,0) -> 5 | M10: =sum(K10:L10) -> 0
A11: 3 | B11: ='Base del Diseño Curricular'!F74 -> Como aplicar gastos por uso de un servidor | C11: X | F11: X | J11: =if(C11="X",$C$7,0)+if(D11="X",$D$7,0)+if(E11="X",$E$7,0)+if(F11="X",$F$7,0)+if(G11="X",$G$7,0)+if(H11="X",$H$7,0)+if(I11="X",$I$7,0) -> 20 | M11: =sum(K11:L11) -> 0
A12: 4 | B12: ='Base del Diseño Curricular'!F75 -> Creacion de variables de centro de costos | C12: X | E12: X | F12: X | G12: X | J12: =IF(C12="X",$C$7,0)+IF(D12="X",$D$7,0)+IF(E12="X",$E$7,0)+IF(F12="X",$F$7,0)+IF(G12="X",$G$7,0)+IF(H12="X",$H$7,0)+IF(I12="X",$I$7,0) -> 40 | M12: =sum(K12:L12) -> 0
A13: 5 | B13: ='Base del Diseño Curricular'!F76 | J13: =if(C13="X",$C$7,0)+if(D13="X",$D$7,0)+if(E13="X",$E$7,0)+if(F13="X",$F$7,0)+if(G13="X",$G$7,0)+if(H13="X",$H$7,0)+if(I13="X",$I$7,0) -> 0 | M13: =sum(K13:L13) -> 0
A14: 6 | B14: ='Base del Diseño Curricular'!F77 | J14: =IF(C14="X",$C$7,0)+IF(D14="X",$D$7,0)+IF(E14="X",$E$7,0)+IF(F14="X",$F$7,0)+IF(G14="X",$G$7,0)+IF(H14="X",$H$7,0)+IF(I14="X",$I$7,0) -> 0 | M14: =sum(K14:L14) -> 0
I15: Tiempo Total en minutos | J15: =SUM(J9:J14) -> 100 | L15: Total Ponderacion | M15: =sum(M9:M14) -> 2
A17: Notas:
A18: Colocar X en la casilla del recurso que se utilizara
A19: Se recomienda que la sumatoria de los minutos no supere los 120 minutos semanales

Sheet S12
A1: Mes | B1: Abril
A2: Semana | B2: 12
A3: Concepto Principal | B3: ='Base del Diseño Curricular'!B72 -> Análisis Financiero y Experimentos Avanzados en Simio
A4: Tema | B4: ='Base del Diseño Curricular'!D79 -> Análisis de resultados en Simio
A6: Numeral | B6: Recurso | C6: Presentación | E6: Video | F6: Lectura | G6: Ejercicio | I6: Cuestionario | K6: Total de Tiempo | L6: Ejercicio | M6: Cuestionario | N6: Total Ponderación
B7: Tiempo aproximado en minutos | C7: 15 | D7: 5 | E7: 15 | F7: 20 | G7: 30 | H7: 5 | I7: 5 | J7: 15 | L7: Ponderación | M7: Ponderación
B8: Sub Tema
A9: 1 | B9: ='Base del Diseño Curricular'!F79 -> Uso de la tabla pivote de resultados | D9: X | E9: X | J9: X | K9: =if(C9="X",$C$7,0)+if(E9="X",$E$7,0)+if(D9="X",$D$7,0)+if(F9="X",$F$7,0)+if(G9="X",$G$7,0)+if(H9="X",$H$7,0)+if(I9="X",$I$7,0)+if(J9="X",$J$7,0) -> 35 | M9: 2 | N9: =sum(L9:M9) -> 2
A10: 2 | B10: ='Base del Diseño Curricular'!F80 -> Visualización y generación de reportes | D10: X | F10: X | G10: X | K10: =if(C10="X",$C$7,0)+if(E10="X",$E$7,0)+if(D10="X",$D$7,0)+if(F10="X",$F$7,0)+if(G10="X",$G$7,0)+if(H10="X",$H$7,0)+if(I10="X",$I$7,0)+if(J10="X",$J$7,0) -> 55 | L10: 2 | N10: =sum(L10:M10) -> 2
A11: 3 | B11: ='Base del Diseño Curricular'!F81 -> Generación y visualización de dashboards | D11: X | H11: X | K11: =if(C11="X",$C$7,0)+if(E11="X",$E$7,0)+if(D11="X",$D$7,0)+if(F11="X",$F$7,0)+if(G11="X",$G$7,0)+if(H11="X",$H$7,0)+if(I11="X",$I$7,0)+if(J11="X",$J$7,0) -> 10 | N11: =sum(L11:M11) -> 0
A12: 4 | K12: =if(C12="X",$C$7,0)+if(E12="X",$E$7,0)+if(D12="X",$D$7,0)+if(F12="X",$F$7,0)+if(G12="X",$G$7,0)+if(H12="X",$H$7,0)+if(I12="X",$I$7,0)+if(J12="X",$J$7,0) -> 0 | N12: =sum(L12:M12) -> 0
A13: 5 | K13: =if(C13="X",$C$7,0)+if(E13="X",$E$7,0)+if(D13="X",$D$7,0)+if(F13="X",$F$7,0)+if(G13="X",$G$7,0)+if(H13="X",$H$7,0)+if(I13="X",$I$7,0)+if(J13="X",$J$7,0) -> 0 | N13: =sum(L13:M13) -> 0
A14: 6 | K14: =if(C14="X",$C$7,0)+if(E14="X",$E$7,0)+if(D14="X",$D$7,0)+if(F14="X",$F$7,0)+if(G14="X",$G$7,0)+if(H14="X",$H$7,0)+if(I14="X",$I$7,0)+if(J14="X",$J$7,0) -> 0 | N14: =sum(L14:M14) -> 0
A15: 7 | K15: =if(C15="X",$C$7,0)+if(E15="X",$E$7,0)+if(D15="X",$D$7,0)+if(F15="X",$F$7,0)+if(G15="X",$G$7,0)+if(H15="X",$H$7,0)+if(I15="X",$I$7,0)+if(J15="X",$J$7,0) -> 0
J16: Tiempo Total en minutos | K16: =SUM(K9:K15) -> 100 | M16: Total Ponderacion | N16: =sum(N9:N14) -> 4
A18: Notas:
A19: Colocar X en la casilla del recurso que se utilizara
A20: Se recomienda que la sumatoria de los minutos no supere los 120 minutos semanales

Sheet S13
A1: Mes | B1: Abril
A2: Semana | B2: 13
A3: Concepto Principal | B3: ='Base del Diseño Curricular'!B72 -> Análisis Financiero y Experimentos Avanzados en Simio
A4: Tema | B4: ='Base del Diseño Curricular'!D86 -> Experimentos
A6: Numeral | B6: Recurso | C6: Presentación | E6: Video | F6: Lectura | G6: Ejercicio | I6: Cuestionario | K6: Total de Tiempo | L6: Ejercicio | M6: Cuestionario | N6: Total Ponderación
B7: Tiempo aproximado en minutos | C7: 10 | D7: 5 | E7: 10 | F7: 10 | G7: 30 | H7: 5 | I7: 5 | J7: 15 | L7: Ponderación | M7: Ponderación
B8: Sub Tema
A9: 1 | B9: ='Base del Diseño Curricular'!F86 -> ¿Qué son experimentos? | D9: X | J9: X | K9: =if(C9="X",$C$7,0)+if(E9="X",$E$7,0)+if(D9="X",$D$7,0)+if(F9="X",$F$7,0)+if(G9="X",$G$7,0)+if(H9="X",$H$7,0)+if(I9="X",$I$7,0)+if(J9="X",$J$7,0) -> 20 | M9: 2 | N9: =sum(L9:M9) -> 2
A10: 2 | B10: ='Base del Diseño Curricular'!F87 -> ¿Qué son escenarios? | D10: X | E10: X | K10: =if(C10="X",$C$7,0)+if(E10="X",$E$7,0)+if(D10="X",$D$7,0)+if(F10="X",$F$7,0)+if(G10="X",$G$7,0)+if(H10="X",$H$7,0)+if(I10="X",$I$7,0)+if(J10="X",$J$7,0) -> 15 | N10: =sum(L10:M10) -> 0
A11: 3 | B11: ='Base del Diseño Curricular'!F88 -> Parámetros de experimentos | D11: X | K11: =if(C11="X",$C$7,0)+if(E11="X",$E$7,0)+if(D11="X",$D$7,0)+if(F11="X",$F$7,0)+if(G11="X",$G$7,0)+if(H11="X",$H$7,0)+if(I11="X",$I$7,0)+if(J11="X",$J$7,0) -> 5 | N11: =sum(L11:M11) -> 0
A12: 4 | B12: ='Base del Diseño Curricular'!F89 -> Configuración de experimentos | D12: X | K12: =if(C12="X",$C$7,0)+if(E12="X",$E$7,0)+if(D12="X",$D$7,0)+if(F12="X",$F$7,0)+if(G12="X",$G$7,0)+if(H12="X",$H$7,0)+if(I12="X",$I$7,0)+if(J12="X",$J$7,0) -> 5 | N12: =sum(L12:M12) -> 0
A13: 5 | B13: ='Base del Diseño Curricular'!F90 -> Ejecución de experimentos | D13: X | G13: X | K13: =if(C13="X",$C$7,0)+if(E13="X",$E$7,0)+if(D13="X",$D$7,0)+if(F13="X",$F$7,0)+if(G13="X",$G$7,0)+if(H13="X",$H$7,0)+if(I13="X",$I$7,0)+if(J13="X",$J$7,0) -> 35 | L13: 2 | N13: =sum(L13:M13) -> 2
A14: 6 | B14: ='Base del Diseño Curricular'!F91 -> Análisis de resutaltados | D14: X | F14: X | K14: =if(C14="X",$C$7,0)+if(E14="X",$E$7,0)+if(D14="X",$D$7,0)+if(F14="X",$F$7,0)+if(G14="X",$G$7,0)+if(H14="X",$H$7,0)+if(I14="X",$I$7,0)+if(J14="X",$J$7,0) -> 15 | N14: =sum(L14:M14) -> 0
A15: 7 | B15: ='Base del Diseño Curricular'!F92 -> Análisis comparativo | D15: X | K15: =if(C15="X",$C$7,0)+if(E15="X",$E$7,0)+if(D15="X",$D$7,0)+if(F15="X",$F$7,0)+if(G15="X",$G$7,0)+if(H15="X",$H$7,0)+if(I15="X",$I$7,0)+if(J15="X",$J$7,0) -> 5
J16: Tiempo Total en minutos | K16: =SUM(K9:K15) -> 100 | M16: Total Ponderacion | N16: =sum(N9:N14) -> 4
A18: Notas:
A19: Colocar X en la casilla del recurso que se utilizara
A20: Se recomienda que la sumatoria de los minutos no supere los 120 minutos semanales

Sheet S14
A1: Mes | B1: Abril
A2: Semana | B2: 14
A3: Concepto Principal | B3: ='Base del Diseño Curricular'!B72 -> Análisis Financiero y Experimentos Avanzados en Simio
A4: Tema | B4: ='Base del Diseño Curricular'!D93 -> Aplicacion de fluidos usando Simio
A6: Numeral | B6: Recurso | C6: Presentación | D6: Video | E6: Lectura | F6: Ejercicio | H6: Cuestionario | J6: Total de Tiempo | K6: Ejercicio | L6: Cuestionario | M6: Total Ponderación
B7: Tiempo aproximado en minutos | C7: 8 | D7: 11 | E7: 15 | F7: 30 | G7: 5 | H7: 5 | I7: 15 | K7: Ponderación | L7: Ponderación
B8: Sub Tema
A9: 1 | B9: ='Base del Diseño Curricular'!F93 -> Introduccion a la libreria de flujos | C9: X | E9: X | J9: =if(C9="X",$C$7,0)+if(D9="X",$D$7,0)+if(E9="X",$E$7,0)+if(F9="X",$F$7,0)+if(G9="X",$G$7,0)+if(H9="X",$H$7,0)+if(I9="X",$I$7,0) -> 23 | M9: =sum(K9:L9) -> 0
A10: 2 | B10: ='Base del Diseño Curricular'!F94 -> Explicacion de como podemos aplicarla en nuestros modelos | C10: X | D10: X | J10: =IF(C10="X",$C$7,0)+IF(D10="X",$D$7,0)+IF(E10="X",$E$7,0)+IF(F10="X",$F$7,0)+IF(G10="X",$G$7,0)+IF(H10="X",$H$7,0)+IF(I10="X",$I$7,0) -> 19 | M10: =sum(K10:L10) -> 0
A11: 3 | B11: ='Base del Diseño Curricular'!F95 -> Componentes principales de la libreria de flujos | C11: X | F11: X | G11: X | I11: X | J11: =if(C11="X",$C$7,0)+if(D11="X",$D$7,0)+if(E11="X",$E$7,0)+if(F11="X",$F$7,0)+if(G11="X",$G$7,0)+if(H11="X",$H$7,0)+if(I11="X",$I$7,0) -> 58 | L11: 2 | M11: =sum(K11:L11) -> 2
A12: 4 | B12: ='Base del Diseño Curricular'!F96 | J12: =IF(C12="X",$C$7,0)+IF(D12="X",$D$7,0)+IF(E12="X",$E$7,0)+IF(F12="X",$F$7,0)+IF(G12="X",$G$7,0)+IF(H12="X",$H$7,0)+IF(I12="X",$I$7,0) -> 0 | M12: =sum(K12:L12) -> 0
A13: 5 | B13: ='Base del Diseño Curricular'!F97 | J13: =if(C13="X",$C$7,0)+if(D13="X",$D$7,0)+if(E13="X",$E$7,0)+if(F13="X",$F$7,0)+if(G13="X",$G$7,0)+if(H13="X",$H$7,0)+if(I13="X",$I$7,0) -> 0 | M13: =sum(K13:L13) -> 0
A14: 6 | B14: ='Base del Diseño Curricular'!F98 | J14: =IF(C14="X",$C$7,0)+IF(D14="X",$D$7,0)+IF(E14="X",$E$7,0)+IF(F14="X",$F$7,0)+IF(G14="X",$G$7,0)+IF(H14="X",$H$7,0)+IF(I14="X",$I$7,0) -> 0 | M14: =sum(K14:L14) -> 0
I15: Tiempo Total en minutos | J15: =SUM(J9:J14) -> 100 | L15: Total Ponderacion | M15: =sum(M9:M14) -> 2
A17: Notas:
A18: Colocar X en la casilla del recurso que se utilizara
A19: Se recomienda que la sumatoria de los minutos no supere los 120 minutos semanales
